[Sun Sep 25 06:46:29.747220 2016] [mpm_event:notice] [pid 576:tid 140297302812544] AH00489: Apache/2.4.7 (Ubuntu) mod_wsgi/3.4 Python/2.7.6 configured -- resuming normal operations
[Sun Sep 25 06:46:29.750281 2016] [core:notice] [pid 576:tid 140297302812544] AH00094: Command line: '/usr/sbin/apache2'
[Sun Sep 25 08:12:22.422259 2016] [:info] [pid 13485:tid 140297201092352] [client 88.190.58.150:64003] mod_wsgi (pid=13485, process='', application='ec2-52-57-15-38.eu-central-1.compute.amazonaws.com|'): Loading WSGI script '/var/www/myapp.wsgi'.
[Sun Sep 25 08:13:03.782932 2016] [:info] [pid 13486:tid 140297086416640] [client 88.190.58.150:64030] mod_wsgi (pid=13486, process='', application='ec2-52-57-15-38.eu-central-1.compute.amazonaws.com|'): Loading WSGI script '/var/www/myapp.wsgi'., referer: http://ec2-52-57-15-38.eu-central-1.compute.amazonaws.com/frames/
[Sun Sep 25 08:13:13.646151 2016] [:error] [pid 13486:tid 140297052845824] done!
[Sun Sep 25 08:14:29.839451 2016] [:error] [pid 13486:tid 140296926955264] [client 88.190.58.150:64048] mod_wsgi (pid=13486): Exception occurred processing WSGI script '/var/www/myapp.wsgi'., referer: http://ec2-52-57-15-38.eu-central-1.compute.amazonaws.com/reports/new?
[Sun Sep 25 08:14:29.839497 2016] [:error] [pid 13486:tid 140296926955264] [client 88.190.58.150:64048] Traceback (most recent call last):, referer: http://ec2-52-57-15-38.eu-central-1.compute.amazonaws.com/reports/new?
[Sun Sep 25 08:14:29.839523 2016] [:error] [pid 13486:tid 140296926955264] [client 88.190.58.150:64048]   File "/usr/lib/python2.7/dist-packages/flask/app.py", line 1836, in __call__, referer: http://ec2-52-57-15-38.eu-central-1.compute.amazonaws.com/reports/new?
[Sun Sep 25 08:14:29.839940 2016] [:error] [pid 13486:tid 140296926955264] [client 88.190.58.150:64048]     return self.wsgi_app(environ, start_response), referer: http://ec2-52-57-15-38.eu-central-1.compute.amazonaws.com/reports/new?
[Sun Sep 25 08:14:29.839955 2016] [:error] [pid 13486:tid 140296926955264] [client 88.190.58.150:64048]   File "/usr/lib/python2.7/dist-packages/flask/app.py", line 1820, in wsgi_app, referer: http://ec2-52-57-15-38.eu-central-1.compute.amazonaws.com/reports/new?
[Sun Sep 25 08:14:29.839973 2016] [:error] [pid 13486:tid 140296926955264] [client 88.190.58.150:64048]     response = self.make_response(self.handle_exception(e)), referer: http://ec2-52-57-15-38.eu-central-1.compute.amazonaws.com/reports/new?
[Sun Sep 25 08:14:29.839985 2016] [:error] [pid 13486:tid 140296926955264] [client 88.190.58.150:64048]   File "/usr/lib/python2.7/dist-packages/flask/app.py", line 1403, in handle_exception, referer: http://ec2-52-57-15-38.eu-central-1.compute.amazonaws.com/reports/new?
[Sun Sep 25 08:14:29.839998 2016] [:error] [pid 13486:tid 140296926955264] [client 88.190.58.150:64048]     reraise(exc_type, exc_value, tb), referer: http://ec2-52-57-15-38.eu-central-1.compute.amazonaws.com/reports/new?
[Sun Sep 25 08:14:29.840007 2016] [:error] [pid 13486:tid 140296926955264] [client 88.190.58.150:64048]   File "/usr/lib/python2.7/dist-packages/flask/app.py", line 1817, in wsgi_app, referer: http://ec2-52-57-15-38.eu-central-1.compute.amazonaws.com/reports/new?
[Sun Sep 25 08:14:29.840018 2016] [:error] [pid 13486:tid 140296926955264] [client 88.190.58.150:64048]     response = self.full_dispatch_request(), referer: http://ec2-52-57-15-38.eu-central-1.compute.amazonaws.com/reports/new?
[Sun Sep 25 08:14:29.840027 2016] [:error] [pid 13486:tid 140296926955264] [client 88.190.58.150:64048]   File "/usr/lib/python2.7/dist-packages/flask/app.py", line 1477, in full_dispatch_request, referer: http://ec2-52-57-15-38.eu-central-1.compute.amazonaws.com/reports/new?
[Sun Sep 25 08:14:29.840038 2016] [:error] [pid 13486:tid 140296926955264] [client 88.190.58.150:64048]     rv = self.handle_user_exception(e), referer: http://ec2-52-57-15-38.eu-central-1.compute.amazonaws.com/reports/new?
[Sun Sep 25 08:14:29.840046 2016] [:error] [pid 13486:tid 140296926955264] [client 88.190.58.150:64048]   File "/usr/lib/python2.7/dist-packages/flask/app.py", line 1381, in handle_user_exception, referer: http://ec2-52-57-15-38.eu-central-1.compute.amazonaws.com/reports/new?
[Sun Sep 25 08:14:29.840069 2016] [:error] [pid 13486:tid 140296926955264] [client 88.190.58.150:64048]     reraise(exc_type, exc_value, tb), referer: http://ec2-52-57-15-38.eu-central-1.compute.amazonaws.com/reports/new?
[Sun Sep 25 08:14:29.840077 2016] [:error] [pid 13486:tid 140296926955264] [client 88.190.58.150:64048]   File "/usr/lib/python2.7/dist-packages/flask/app.py", line 1475, in full_dispatch_request, referer: http://ec2-52-57-15-38.eu-central-1.compute.amazonaws.com/reports/new?
[Sun Sep 25 08:14:29.840089 2016] [:error] [pid 13486:tid 140296926955264] [client 88.190.58.150:64048]     rv = self.dispatch_request(), referer: http://ec2-52-57-15-38.eu-central-1.compute.amazonaws.com/reports/new?
[Sun Sep 25 08:14:29.840097 2016] [:error] [pid 13486:tid 140296926955264] [client 88.190.58.150:64048]   File "/usr/lib/python2.7/dist-packages/flask/app.py", line 1461, in dispatch_request, referer: http://ec2-52-57-15-38.eu-central-1.compute.amazonaws.com/reports/new?
[Sun Sep 25 08:14:29.840108 2016] [:error] [pid 13486:tid 140296926955264] [client 88.190.58.150:64048]     return self.view_functions[rule.endpoint](**req.view_args), referer: http://ec2-52-57-15-38.eu-central-1.compute.amazonaws.com/reports/new?
[Sun Sep 25 08:14:29.840118 2016] [:error] [pid 13486:tid 140296926955264] [client 88.190.58.150:64048]   File "/var/www/ItemCatalog/finalProject.py", line 69, in decorated_function, referer: http://ec2-52-57-15-38.eu-central-1.compute.amazonaws.com/reports/new?
[Sun Sep 25 08:14:29.840371 2016] [:error] [pid 13486:tid 140296926955264] [client 88.190.58.150:64048]     return f(*args, **kwargs), referer: http://ec2-52-57-15-38.eu-central-1.compute.amazonaws.com/reports/new?
[Sun Sep 25 08:14:29.840387 2016] [:error] [pid 13486:tid 140296926955264] [client 88.190.58.150:64048]   File "/var/www/ItemCatalog/finalProject.py", line 507, in newSingleReport, referer: http://ec2-52-57-15-38.eu-central-1.compute.amazonaws.com/reports/new?
[Sun Sep 25 08:14:29.840402 2016] [:error] [pid 13486:tid 140296926955264] [client 88.190.58.150:64048]     session.commit(), referer: http://ec2-52-57-15-38.eu-central-1.compute.amazonaws.com/reports/new?
[Sun Sep 25 08:14:29.840414 2016] [:error] [pid 13486:tid 140296926955264] [client 88.190.58.150:64048]   File "/usr/lib/python2.7/dist-packages/sqlalchemy/orm/session.py", line 721, in commit, referer: http://ec2-52-57-15-38.eu-central-1.compute.amazonaws.com/reports/new?
[Sun Sep 25 08:14:29.840842 2016] [:error] [pid 13486:tid 140296926955264] [client 88.190.58.150:64048]     self.transaction.commit(), referer: http://ec2-52-57-15-38.eu-central-1.compute.amazonaws.com/reports/new?
[Sun Sep 25 08:14:29.840855 2016] [:error] [pid 13486:tid 140296926955264] [client 88.190.58.150:64048]   File "/usr/lib/python2.7/dist-packages/sqlalchemy/orm/session.py", line 354, in commit, referer: http://ec2-52-57-15-38.eu-central-1.compute.amazonaws.com/reports/new?
[Sun Sep 25 08:14:29.840870 2016] [:error] [pid 13486:tid 140296926955264] [client 88.190.58.150:64048]     self._prepare_impl(), referer: http://ec2-52-57-15-38.eu-central-1.compute.amazonaws.com/reports/new?
[Sun Sep 25 08:14:29.840878 2016] [:error] [pid 13486:tid 140296926955264] [client 88.190.58.150:64048]   File "/usr/lib/python2.7/dist-packages/sqlalchemy/orm/session.py", line 334, in _prepare_impl, referer: http://ec2-52-57-15-38.eu-central-1.compute.amazonaws.com/reports/new?
[Sun Sep 25 08:14:29.840931 2016] [:error] [pid 13486:tid 140296926955264] [client 88.190.58.150:64048]     self.session.flush(), referer: http://ec2-52-57-15-38.eu-central-1.compute.amazonaws.com/reports/new?
[Sun Sep 25 08:14:29.840942 2016] [:error] [pid 13486:tid 140296926955264] [client 88.190.58.150:64048]   File "/usr/lib/python2.7/dist-packages/sqlalchemy/orm/session.py", line 1818, in flush, referer: http://ec2-52-57-15-38.eu-central-1.compute.amazonaws.com/reports/new?
[Sun Sep 25 08:14:29.840954 2016] [:error] [pid 13486:tid 140296926955264] [client 88.190.58.150:64048]     self._flush(objects), referer: http://ec2-52-57-15-38.eu-central-1.compute.amazonaws.com/reports/new?
[Sun Sep 25 08:14:29.840968 2016] [:error] [pid 13486:tid 140296926955264] [client 88.190.58.150:64048]   File "/usr/lib/python2.7/dist-packages/sqlalchemy/orm/session.py", line 1936, in _flush, referer: http://ec2-52-57-15-38.eu-central-1.compute.amazonaws.com/reports/new?
[Sun Sep 25 08:14:29.840981 2016] [:error] [pid 13486:tid 140296926955264] [client 88.190.58.150:64048]     transaction.rollback(_capture_exception=True), referer: http://ec2-52-57-15-38.eu-central-1.compute.amazonaws.com/reports/new?
[Sun Sep 25 08:14:29.840990 2016] [:error] [pid 13486:tid 140296926955264] [client 88.190.58.150:64048]   File "/usr/lib/python2.7/dist-packages/sqlalchemy/util/langhelpers.py", line 58, in __exit__, referer: http://ec2-52-57-15-38.eu-central-1.compute.amazonaws.com/reports/new?
[Sun Sep 25 08:14:29.841182 2016] [:error] [pid 13486:tid 140296926955264] [client 88.190.58.150:64048]     compat.reraise(exc_type, exc_value, exc_tb), referer: http://ec2-52-57-15-38.eu-central-1.compute.amazonaws.com/reports/new?
[Sun Sep 25 08:14:29.841195 2016] [:error] [pid 13486:tid 140296926955264] [client 88.190.58.150:64048]   File "/usr/lib/python2.7/dist-packages/sqlalchemy/orm/session.py", line 1900, in _flush, referer: http://ec2-52-57-15-38.eu-central-1.compute.amazonaws.com/reports/new?
[Sun Sep 25 08:14:29.841209 2016] [:error] [pid 13486:tid 140296926955264] [client 88.190.58.150:64048]     flush_context.execute(), referer: http://ec2-52-57-15-38.eu-central-1.compute.amazonaws.com/reports/new?
[Sun Sep 25 08:14:29.841219 2016] [:error] [pid 13486:tid 140296926955264] [client 88.190.58.150:64048]   File "/usr/lib/python2.7/dist-packages/sqlalchemy/orm/unitofwork.py", line 372, in execute, referer: http://ec2-52-57-15-38.eu-central-1.compute.amazonaws.com/reports/new?
[Sun Sep 25 08:14:29.841356 2016] [:error] [pid 13486:tid 140296926955264] [client 88.190.58.150:64048]     rec.execute(self), referer: http://ec2-52-57-15-38.eu-central-1.compute.amazonaws.com/reports/new?
[Sun Sep 25 08:14:29.841369 2016] [:error] [pid 13486:tid 140296926955264] [client 88.190.58.150:64048]   File "/usr/lib/python2.7/dist-packages/sqlalchemy/orm/unitofwork.py", line 525, in execute, referer: http://ec2-52-57-15-38.eu-central-1.compute.amazonaws.com/reports/new?
[Sun Sep 25 08:14:29.841384 2016] [:error] [pid 13486:tid 140296926955264] [client 88.190.58.150:64048]     uow, referer: http://ec2-52-57-15-38.eu-central-1.compute.amazonaws.com/reports/new?
[Sun Sep 25 08:14:29.841394 2016] [:error] [pid 13486:tid 140296926955264] [client 88.190.58.150:64048]   File "/usr/lib/python2.7/dist-packages/sqlalchemy/orm/persistence.py", line 64, in save_obj, referer: http://ec2-52-57-15-38.eu-central-1.compute.amazonaws.com/reports/new?
[Sun Sep 25 08:14:29.841617 2016] [:error] [pid 13486:tid 140296926955264] [client 88.190.58.150:64048]     table, insert), referer: http://ec2-52-57-15-38.eu-central-1.compute.amazonaws.com/reports/new?
[Sun Sep 25 08:14:29.841630 2016] [:error] [pid 13486:tid 140296926955264] [client 88.190.58.150:64048]   File "/usr/lib/python2.7/dist-packages/sqlalchemy/orm/persistence.py", line 569, in _emit_insert_statements, referer: http://ec2-52-57-15-38.eu-central-1.compute.amazonaws.com/reports/new?
[Sun Sep 25 08:14:29.841645 2016] [:error] [pid 13486:tid 140296926955264] [client 88.190.58.150:64048]     execute(statement, params), referer: http://ec2-52-57-15-38.eu-central-1.compute.amazonaws.com/reports/new?
[Sun Sep 25 08:14:29.841656 2016] [:error] [pid 13486:tid 140296926955264] [client 88.190.58.150:64048]   File "/usr/lib/python2.7/dist-packages/sqlalchemy/engine/base.py", line 662, in execute, referer: http://ec2-52-57-15-38.eu-central-1.compute.amazonaws.com/reports/new?
[Sun Sep 25 08:14:29.841963 2016] [:error] [pid 13486:tid 140296926955264] [client 88.190.58.150:64048]     params), referer: http://ec2-52-57-15-38.eu-central-1.compute.amazonaws.com/reports/new?
[Sun Sep 25 08:14:29.841976 2016] [:error] [pid 13486:tid 140296926955264] [client 88.190.58.150:64048]   File "/usr/lib/python2.7/dist-packages/sqlalchemy/engine/base.py", line 761, in _execute_clauseelement, referer: http://ec2-52-57-15-38.eu-central-1.compute.amazonaws.com/reports/new?
[Sun Sep 25 08:14:29.841996 2016] [:error] [pid 13486:tid 140296926955264] [client 88.190.58.150:64048]     compiled_sql, distilled_params, referer: http://ec2-52-57-15-38.eu-central-1.compute.amazonaws.com/reports/new?
[Sun Sep 25 08:14:29.842005 2016] [:error] [pid 13486:tid 140296926955264] [client 88.190.58.150:64048]   File "/usr/lib/python2.7/dist-packages/sqlalchemy/engine/base.py", line 874, in _execute_context, referer: http://ec2-52-57-15-38.eu-central-1.compute.amazonaws.com/reports/new?
[Sun Sep 25 08:14:29.842017 2016] [:error] [pid 13486:tid 140296926955264] [client 88.190.58.150:64048]     context), referer: http://ec2-52-57-15-38.eu-central-1.compute.amazonaws.com/reports/new?
[Sun Sep 25 08:14:29.842025 2016] [:error] [pid 13486:tid 140296926955264] [client 88.190.58.150:64048]   File "/usr/lib/python2.7/dist-packages/sqlalchemy/engine/base.py", line 1024, in _handle_dbapi_exception, referer: http://ec2-52-57-15-38.eu-central-1.compute.amazonaws.com/reports/new?
[Sun Sep 25 08:14:29.842036 2016] [:error] [pid 13486:tid 140296926955264] [client 88.190.58.150:64048]     exc_info, referer: http://ec2-52-57-15-38.eu-central-1.compute.amazonaws.com/reports/new?
[Sun Sep 25 08:14:29.842046 2016] [:error] [pid 13486:tid 140296926955264] [client 88.190.58.150:64048]   File "/usr/lib/python2.7/dist-packages/sqlalchemy/util/compat.py", line 196, in raise_from_cause, referer: http://ec2-52-57-15-38.eu-central-1.compute.amazonaws.com/reports/new?
[Sun Sep 25 08:14:29.842097 2016] [:error] [pid 13486:tid 140296926955264] [client 88.190.58.150:64048]     reraise(type(exception), exception, tb=exc_tb), referer: http://ec2-52-57-15-38.eu-central-1.compute.amazonaws.com/reports/new?
[Sun Sep 25 08:14:29.842108 2016] [:error] [pid 13486:tid 140296926955264] [client 88.190.58.150:64048]   File "/usr/lib/python2.7/dist-packages/sqlalchemy/engine/base.py", line 867, in _execute_context, referer: http://ec2-52-57-15-38.eu-central-1.compute.amazonaws.com/reports/new?
[Sun Sep 25 08:14:29.842122 2016] [:error] [pid 13486:tid 140296926955264] [client 88.190.58.150:64048]     context), referer: http://ec2-52-57-15-38.eu-central-1.compute.amazonaws.com/reports/new?
[Sun Sep 25 08:14:29.842132 2016] [:error] [pid 13486:tid 140296926955264] [client 88.190.58.150:64048]   File "/usr/lib/python2.7/dist-packages/sqlalchemy/engine/default.py", line 324, in do_execute, referer: http://ec2-52-57-15-38.eu-central-1.compute.amazonaws.com/reports/new?
[Sun Sep 25 08:14:29.842296 2016] [:error] [pid 13486:tid 140296926955264] [client 88.190.58.150:64048]     cursor.execute(statement, parameters), referer: http://ec2-52-57-15-38.eu-central-1.compute.amazonaws.com/reports/new?
[Sun Sep 25 08:14:29.842375 2016] [:error] [pid 13486:tid 140296926955264] [client 88.190.58.150:64048] DataError: (DataError) invalid input syntax for integer: "sdgdsdg", referer: http://ec2-52-57-15-38.eu-central-1.compute.amazonaws.com/reports/new?
[Sun Sep 25 08:14:29.842382 2016] [:error] [pid 13486:tid 140296926955264] [client 88.190.58.150:64048] LINE 1: ... '', '', '', '', 'gsdgsdgd', 'gsdgsdgddg@dsf.fr', 'sdgdsdg',..., referer: http://ec2-52-57-15-38.eu-central-1.compute.amazonaws.com/reports/new?
[Sun Sep 25 08:14:29.842385 2016] [:error] [pid 13486:tid 140296926955264] [client 88.190.58.150:64048]                                                              ^, referer: http://ec2-52-57-15-38.eu-central-1.compute.amazonaws.com/reports/new?
[Sun Sep 25 08:14:29.842390 2016] [:error] [pid 13486:tid 140296926955264] [client 88.190.58.150:64048]  'INSERT INTO report (site_name, site_full_adress, site_adress_number, site_adress_street, site_adress_postcode, site_adress_city, site_administrative_area, site_adress_country, "site_ERPcategory", "site_ERPtype", client_lastname, client_firstname, client_full_adress, client_adress_number, client_adress_street, client_adress_postcode, client_adress_city, client_administrative_area, client_adress_country, client_phone, client_mail, report_number, "report_visitDate", "report_redactionDate", report_picture, "report_pictureOrientation", editor_lastname, editor_firstname, editor_full_adress, editor_adress_number, editor_adress_street, editor_adress_postcode, editor_adress_city, editor_administrative_area, editor_adress_country, editor_phone, editor_mail, frame_choice, user_id) VALUES (%(site_name)s, %(site_full_adress)s, %(site_adress_number)s, %(site_adress_street)s, %(site_adress_postcode)s, %(site_adress_city)s, %(site_administrative_area)s, %(site_adress_country)s, %(site_ERPcategory)s, %(site_ERPtype)s, %(client_lastname)s, %(client_firstname)s, %(client_full_adress)s, %(client_adress_number)s, %(client_adress_street)s, %(client_adress_postcode)s, %(client_adress_city)s, %(client_administrative_area)s, %(client_adress_country)s, %(client_phone)s, %(client_mail)s, %(report_number)s, %(report_visitDate)s, %(report_redactionDate)s, %(report_picture)s, %(report_pictureOrientation)s, %(editor_lastname)s, %(editor_firstname)s, %(editor_full_adress)s, %(editor_adress_number)s, %(editor_adress_street)s, %(editor_adress_postcode)s, %(editor_adress_city)s, %(editor_administrative_area)s, %(editor_adress_country)s, %(editor_phone)s, %(editor_mail)s, %(frame_choice)s, %(user_id)s) RETURNING report.id' {'site_name': u'dsgsdg', 'report_number': u'sdgdsdg', 'editor_full_adress': u'dsgsdg', 'editor_adress_street': u'', 'client_lastname': u'sgsdgdsgsdgds', 'site_ERPtype': u'sdgsdgsdg', 'editor_adress_city': u'', 'client_phone': u'gsdgsdgd', 'editor_administrative_area': u'', 'client_firstname': u'sggdgdsg', 'user_id': 11, 'site_full_adress': u'dsgsdg', 'client_full_adress': u'48 rue raffet 75016 PARIS', 'report_visitDate': u'2016-09-16', 'report_redactionDate': u'2016-09-30', 'client_adress_city': u'', 'site_adress_number': u'', 'client_adress_country': u'', 'editor_adress_postcode': u'', 'client_adress_number': u'', 'client_mail': u'gsdgsdgddg@dsf.fr', 'editor_phone': u'sdgsdgsd', 'site_adress_city': u'', 'editor_adress_number': u'', 'editor_adress_country': u'', 'site_adress_postcode': u'', 'site_administrative_area': u'', 'report_pictureOrientation': 'None', 'editor_mail': u'gsdgsdgddg@dsf.fr', 'report_picture': 'undefined.jpg', 'client_administrative_area': u'', 'client_adress_postcode': u'', 'site_ERPcategory': u'5', 'editor_lastname': u'sdgsdg', 'site_adress_street': u'', 'site_adress_country': u'', 'client_adress_street': u'', 'editor_firstname': u'sdgsdgdg', 'frame_choice': 0}, referer: http://ec2-52-57-15-38.eu-central-1.compute.amazonaws.com/reports/new?
[Sun Sep 25 09:20:17.082539 2016] [:error] [pid 13485:tid 140296935347968] [client 88.190.58.150:65209] mod_wsgi (pid=13485): Exception occurred processing WSGI script '/var/www/myapp.wsgi'.
[Sun Sep 25 09:20:17.082577 2016] [:error] [pid 13485:tid 140296935347968] [client 88.190.58.150:65209] Traceback (most recent call last):
[Sun Sep 25 09:20:17.082594 2016] [:error] [pid 13485:tid 140296935347968] [client 88.190.58.150:65209]   File "/usr/lib/python2.7/dist-packages/flask/app.py", line 1836, in __call__
[Sun Sep 25 09:20:17.082932 2016] [:error] [pid 13485:tid 140296935347968] [client 88.190.58.150:65209]     return self.wsgi_app(environ, start_response)
[Sun Sep 25 09:20:17.082951 2016] [:error] [pid 13485:tid 140296935347968] [client 88.190.58.150:65209]   File "/usr/lib/python2.7/dist-packages/flask/app.py", line 1820, in wsgi_app
[Sun Sep 25 09:20:17.082968 2016] [:error] [pid 13485:tid 140296935347968] [client 88.190.58.150:65209]     response = self.make_response(self.handle_exception(e))
[Sun Sep 25 09:20:17.082977 2016] [:error] [pid 13485:tid 140296935347968] [client 88.190.58.150:65209]   File "/usr/lib/python2.7/dist-packages/flask/app.py", line 1403, in handle_exception
[Sun Sep 25 09:20:17.082988 2016] [:error] [pid 13485:tid 140296935347968] [client 88.190.58.150:65209]     reraise(exc_type, exc_value, tb)
[Sun Sep 25 09:20:17.083007 2016] [:error] [pid 13485:tid 140296935347968] [client 88.190.58.150:65209]   File "/usr/lib/python2.7/dist-packages/flask/app.py", line 1817, in wsgi_app
[Sun Sep 25 09:20:17.083033 2016] [:error] [pid 13485:tid 140296935347968] [client 88.190.58.150:65209]     response = self.full_dispatch_request()
[Sun Sep 25 09:20:17.083042 2016] [:error] [pid 13485:tid 140296935347968] [client 88.190.58.150:65209]   File "/usr/lib/python2.7/dist-packages/flask/app.py", line 1477, in full_dispatch_request
[Sun Sep 25 09:20:17.083053 2016] [:error] [pid 13485:tid 140296935347968] [client 88.190.58.150:65209]     rv = self.handle_user_exception(e)
[Sun Sep 25 09:20:17.083061 2016] [:error] [pid 13485:tid 140296935347968] [client 88.190.58.150:65209]   File "/usr/lib/python2.7/dist-packages/flask/app.py", line 1381, in handle_user_exception
[Sun Sep 25 09:20:17.083072 2016] [:error] [pid 13485:tid 140296935347968] [client 88.190.58.150:65209]     reraise(exc_type, exc_value, tb)
[Sun Sep 25 09:20:17.083079 2016] [:error] [pid 13485:tid 140296935347968] [client 88.190.58.150:65209]   File "/usr/lib/python2.7/dist-packages/flask/app.py", line 1475, in full_dispatch_request
[Sun Sep 25 09:20:17.083090 2016] [:error] [pid 13485:tid 140296935347968] [client 88.190.58.150:65209]     rv = self.dispatch_request()
[Sun Sep 25 09:20:17.083097 2016] [:error] [pid 13485:tid 140296935347968] [client 88.190.58.150:65209]   File "/usr/lib/python2.7/dist-packages/flask/app.py", line 1461, in dispatch_request
[Sun Sep 25 09:20:17.083108 2016] [:error] [pid 13485:tid 140296935347968] [client 88.190.58.150:65209]     return self.view_functions[rule.endpoint](**req.view_args)
[Sun Sep 25 09:20:17.083115 2016] [:error] [pid 13485:tid 140296935347968] [client 88.190.58.150:65209]   File "/var/www/ItemCatalog/finalProject.py", line 409, in showAllReports
[Sun Sep 25 09:20:17.083257 2016] [:error] [pid 13485:tid 140296935347968] [client 88.190.58.150:65209]     def showAllReportsJSON():
[Sun Sep 25 09:20:17.083269 2016] [:error] [pid 13485:tid 140296935347968] [client 88.190.58.150:65209]   File "/usr/lib/python2.7/dist-packages/flask/templating.py", line 128, in render_template
[Sun Sep 25 09:20:17.083326 2016] [:error] [pid 13485:tid 140296935347968] [client 88.190.58.150:65209]     context, ctx.app)
[Sun Sep 25 09:20:17.083337 2016] [:error] [pid 13485:tid 140296935347968] [client 88.190.58.150:65209]   File "/usr/lib/python2.7/dist-packages/flask/templating.py", line 110, in _render
[Sun Sep 25 09:20:17.083350 2016] [:error] [pid 13485:tid 140296935347968] [client 88.190.58.150:65209]     rv = template.render(context)
[Sun Sep 25 09:20:17.083361 2016] [:error] [pid 13485:tid 140296935347968] [client 88.190.58.150:65209]   File "/usr/lib/python2.7/dist-packages/jinja2/environment.py", line 969, in render
[Sun Sep 25 09:20:17.083593 2016] [:error] [pid 13485:tid 140296935347968] [client 88.190.58.150:65209]     return self.environment.handle_exception(exc_info, True)
[Sun Sep 25 09:20:17.083605 2016] [:error] [pid 13485:tid 140296935347968] [client 88.190.58.150:65209]   File "/usr/lib/python2.7/dist-packages/jinja2/environment.py", line 742, in handle_exception
[Sun Sep 25 09:20:17.083618 2016] [:error] [pid 13485:tid 140296935347968] [client 88.190.58.150:65209]     reraise(exc_type, exc_value, tb)
[Sun Sep 25 09:20:17.083626 2016] [:error] [pid 13485:tid 140296935347968] [client 88.190.58.150:65209]   File "/var/www/ItemCatalog/templates/reports.html", line 150, in top-level template code
[Sun Sep 25 09:20:17.083686 2016] [:error] [pid 13485:tid 140296935347968] [client 88.190.58.150:65209]     <h3>Editor's name : {{frames[(i.frame_choice)-1].editor_firstname}}</h3>
[Sun Sep 25 09:20:17.083726 2016] [:error] [pid 13485:tid 140296935347968] [client 88.190.58.150:65209] TypeError: unsupported operand type(s) for -: 'NoneType' and 'int'
[Sun Sep 25 09:28:07.234881 2016] [mpm_event:notice] [pid 576:tid 140297302812544] AH00491: caught SIGTERM, shutting down
[Sun Sep 25 09:28:19.534666 2016] [mpm_event:notice] [pid 1237:tid 140591514777472] AH00489: Apache/2.4.7 (Ubuntu) mod_wsgi/3.4 Python/2.7.6 configured -- resuming normal operations
[Sun Sep 25 09:28:19.534989 2016] [core:notice] [pid 1237:tid 140591514777472] AH00094: Command line: '/usr/sbin/apache2'
[Sun Sep 25 09:40:40.426411 2016] [:info] [pid 1240:tid 140591413057280] [client 88.190.58.150:49427] mod_wsgi (pid=1240, process='', application='ec2-52-57-15-38.eu-central-1.compute.amazonaws.com|'): Loading WSGI script '/var/www/myapp.wsgi'.
[Sun Sep 25 09:40:41.043275 2016] [:info] [pid 1241:tid 140591300069120] [client 88.190.58.150:49426] mod_wsgi (pid=1241, process='', application='ec2-52-57-15-38.eu-central-1.compute.amazonaws.com|'): Loading WSGI script '/var/www/myapp.wsgi'., referer: http://ec2-52-57-87-239.eu-central-1.compute.amazonaws.com/
[Sun Sep 25 09:51:38.380282 2016] [:error] [pid 1241:tid 140591182571264] done!
[Sun Sep 25 10:00:20.558512 2016] [:error] [pid 1240:tid 140591274891008] [client 88.190.58.150:49725] mod_wsgi (pid=1240): Exception occurred processing WSGI script '/var/www/myapp.wsgi'., referer: http://ec2-52-57-87-239.eu-central-1.compute.amazonaws.com/reports/new?
[Sun Sep 25 10:00:20.558550 2016] [:error] [pid 1240:tid 140591274891008] [client 88.190.58.150:49725] Traceback (most recent call last):, referer: http://ec2-52-57-87-239.eu-central-1.compute.amazonaws.com/reports/new?
[Sun Sep 25 10:00:20.558566 2016] [:error] [pid 1240:tid 140591274891008] [client 88.190.58.150:49725]   File "/usr/lib/python2.7/dist-packages/flask/app.py", line 1836, in __call__, referer: http://ec2-52-57-87-239.eu-central-1.compute.amazonaws.com/reports/new?
[Sun Sep 25 10:00:20.560744 2016] [:error] [pid 1240:tid 140591274891008] [client 88.190.58.150:49725]     return self.wsgi_app(environ, start_response), referer: http://ec2-52-57-87-239.eu-central-1.compute.amazonaws.com/reports/new?
[Sun Sep 25 10:00:20.560760 2016] [:error] [pid 1240:tid 140591274891008] [client 88.190.58.150:49725]   File "/usr/lib/python2.7/dist-packages/flask/app.py", line 1820, in wsgi_app, referer: http://ec2-52-57-87-239.eu-central-1.compute.amazonaws.com/reports/new?
[Sun Sep 25 10:00:20.560775 2016] [:error] [pid 1240:tid 140591274891008] [client 88.190.58.150:49725]     response = self.make_response(self.handle_exception(e)), referer: http://ec2-52-57-87-239.eu-central-1.compute.amazonaws.com/reports/new?
[Sun Sep 25 10:00:20.560782 2016] [:error] [pid 1240:tid 140591274891008] [client 88.190.58.150:49725]   File "/usr/lib/python2.7/dist-packages/flask/app.py", line 1403, in handle_exception, referer: http://ec2-52-57-87-239.eu-central-1.compute.amazonaws.com/reports/new?
[Sun Sep 25 10:00:20.560791 2016] [:error] [pid 1240:tid 140591274891008] [client 88.190.58.150:49725]     reraise(exc_type, exc_value, tb), referer: http://ec2-52-57-87-239.eu-central-1.compute.amazonaws.com/reports/new?
[Sun Sep 25 10:00:20.560796 2016] [:error] [pid 1240:tid 140591274891008] [client 88.190.58.150:49725]   File "/usr/lib/python2.7/dist-packages/flask/app.py", line 1817, in wsgi_app, referer: http://ec2-52-57-87-239.eu-central-1.compute.amazonaws.com/reports/new?
[Sun Sep 25 10:00:20.560804 2016] [:error] [pid 1240:tid 140591274891008] [client 88.190.58.150:49725]     response = self.full_dispatch_request(), referer: http://ec2-52-57-87-239.eu-central-1.compute.amazonaws.com/reports/new?
[Sun Sep 25 10:00:20.560810 2016] [:error] [pid 1240:tid 140591274891008] [client 88.190.58.150:49725]   File "/usr/lib/python2.7/dist-packages/flask/app.py", line 1477, in full_dispatch_request, referer: http://ec2-52-57-87-239.eu-central-1.compute.amazonaws.com/reports/new?
[Sun Sep 25 10:00:20.560818 2016] [:error] [pid 1240:tid 140591274891008] [client 88.190.58.150:49725]     rv = self.handle_user_exception(e), referer: http://ec2-52-57-87-239.eu-central-1.compute.amazonaws.com/reports/new?
[Sun Sep 25 10:00:20.560823 2016] [:error] [pid 1240:tid 140591274891008] [client 88.190.58.150:49725]   File "/usr/lib/python2.7/dist-packages/flask/app.py", line 1381, in handle_user_exception, referer: http://ec2-52-57-87-239.eu-central-1.compute.amazonaws.com/reports/new?
[Sun Sep 25 10:00:20.560837 2016] [:error] [pid 1240:tid 140591274891008] [client 88.190.58.150:49725]     reraise(exc_type, exc_value, tb), referer: http://ec2-52-57-87-239.eu-central-1.compute.amazonaws.com/reports/new?
[Sun Sep 25 10:00:20.560842 2016] [:error] [pid 1240:tid 140591274891008] [client 88.190.58.150:49725]   File "/usr/lib/python2.7/dist-packages/flask/app.py", line 1475, in full_dispatch_request, referer: http://ec2-52-57-87-239.eu-central-1.compute.amazonaws.com/reports/new?
[Sun Sep 25 10:00:20.560850 2016] [:error] [pid 1240:tid 140591274891008] [client 88.190.58.150:49725]     rv = self.dispatch_request(), referer: http://ec2-52-57-87-239.eu-central-1.compute.amazonaws.com/reports/new?
[Sun Sep 25 10:00:20.560855 2016] [:error] [pid 1240:tid 140591274891008] [client 88.190.58.150:49725]   File "/usr/lib/python2.7/dist-packages/flask/app.py", line 1461, in dispatch_request, referer: http://ec2-52-57-87-239.eu-central-1.compute.amazonaws.com/reports/new?
[Sun Sep 25 10:00:20.560865 2016] [:error] [pid 1240:tid 140591274891008] [client 88.190.58.150:49725]     return self.view_functions[rule.endpoint](**req.view_args), referer: http://ec2-52-57-87-239.eu-central-1.compute.amazonaws.com/reports/new?
[Sun Sep 25 10:00:20.560871 2016] [:error] [pid 1240:tid 140591274891008] [client 88.190.58.150:49725]   File "/var/www/ItemCatalog/finalProject.py", line 69, in decorated_function, referer: http://ec2-52-57-87-239.eu-central-1.compute.amazonaws.com/reports/new?
[Sun Sep 25 10:00:20.561036 2016] [:error] [pid 1240:tid 140591274891008] [client 88.190.58.150:49725]     return f(*args, **kwargs), referer: http://ec2-52-57-87-239.eu-central-1.compute.amazonaws.com/reports/new?
[Sun Sep 25 10:00:20.561048 2016] [:error] [pid 1240:tid 140591274891008] [client 88.190.58.150:49725]   File "/var/www/ItemCatalog/finalProject.py", line 503, in newSingleReport, referer: http://ec2-52-57-87-239.eu-central-1.compute.amazonaws.com/reports/new?
[Sun Sep 25 10:00:20.561059 2016] [:error] [pid 1240:tid 140591274891008] [client 88.190.58.150:49725]     session.commit(), referer: http://ec2-52-57-87-239.eu-central-1.compute.amazonaws.com/reports/new?
[Sun Sep 25 10:00:20.561064 2016] [:error] [pid 1240:tid 140591274891008] [client 88.190.58.150:49725]   File "/usr/lib/python2.7/dist-packages/sqlalchemy/orm/session.py", line 721, in commit, referer: http://ec2-52-57-87-239.eu-central-1.compute.amazonaws.com/reports/new?
[Sun Sep 25 10:00:20.561483 2016] [:error] [pid 1240:tid 140591274891008] [client 88.190.58.150:49725]     self.transaction.commit(), referer: http://ec2-52-57-87-239.eu-central-1.compute.amazonaws.com/reports/new?
[Sun Sep 25 10:00:20.561494 2016] [:error] [pid 1240:tid 140591274891008] [client 88.190.58.150:49725]   File "/usr/lib/python2.7/dist-packages/sqlalchemy/orm/session.py", line 354, in commit, referer: http://ec2-52-57-87-239.eu-central-1.compute.amazonaws.com/reports/new?
[Sun Sep 25 10:00:20.561506 2016] [:error] [pid 1240:tid 140591274891008] [client 88.190.58.150:49725]     self._prepare_impl(), referer: http://ec2-52-57-87-239.eu-central-1.compute.amazonaws.com/reports/new?
[Sun Sep 25 10:00:20.561512 2016] [:error] [pid 1240:tid 140591274891008] [client 88.190.58.150:49725]   File "/usr/lib/python2.7/dist-packages/sqlalchemy/orm/session.py", line 334, in _prepare_impl, referer: http://ec2-52-57-87-239.eu-central-1.compute.amazonaws.com/reports/new?
[Sun Sep 25 10:00:20.561521 2016] [:error] [pid 1240:tid 140591274891008] [client 88.190.58.150:49725]     self.session.flush(), referer: http://ec2-52-57-87-239.eu-central-1.compute.amazonaws.com/reports/new?
[Sun Sep 25 10:00:20.561526 2016] [:error] [pid 1240:tid 140591274891008] [client 88.190.58.150:49725]   File "/usr/lib/python2.7/dist-packages/sqlalchemy/orm/session.py", line 1818, in flush, referer: http://ec2-52-57-87-239.eu-central-1.compute.amazonaws.com/reports/new?
[Sun Sep 25 10:00:20.561534 2016] [:error] [pid 1240:tid 140591274891008] [client 88.190.58.150:49725]     self._flush(objects), referer: http://ec2-52-57-87-239.eu-central-1.compute.amazonaws.com/reports/new?
[Sun Sep 25 10:00:20.561544 2016] [:error] [pid 1240:tid 140591274891008] [client 88.190.58.150:49725]   File "/usr/lib/python2.7/dist-packages/sqlalchemy/orm/session.py", line 1936, in _flush, referer: http://ec2-52-57-87-239.eu-central-1.compute.amazonaws.com/reports/new?
[Sun Sep 25 10:00:20.561553 2016] [:error] [pid 1240:tid 140591274891008] [client 88.190.58.150:49725]     transaction.rollback(_capture_exception=True), referer: http://ec2-52-57-87-239.eu-central-1.compute.amazonaws.com/reports/new?
[Sun Sep 25 10:00:20.561558 2016] [:error] [pid 1240:tid 140591274891008] [client 88.190.58.150:49725]   File "/usr/lib/python2.7/dist-packages/sqlalchemy/util/langhelpers.py", line 58, in __exit__, referer: http://ec2-52-57-87-239.eu-central-1.compute.amazonaws.com/reports/new?
[Sun Sep 25 10:00:20.562252 2016] [:error] [pid 1240:tid 140591274891008] [client 88.190.58.150:49725]     compat.reraise(exc_type, exc_value, exc_tb), referer: http://ec2-52-57-87-239.eu-central-1.compute.amazonaws.com/reports/new?
[Sun Sep 25 10:00:20.562264 2016] [:error] [pid 1240:tid 140591274891008] [client 88.190.58.150:49725]   File "/usr/lib/python2.7/dist-packages/sqlalchemy/orm/session.py", line 1900, in _flush, referer: http://ec2-52-57-87-239.eu-central-1.compute.amazonaws.com/reports/new?
[Sun Sep 25 10:00:20.562277 2016] [:error] [pid 1240:tid 140591274891008] [client 88.190.58.150:49725]     flush_context.execute(), referer: http://ec2-52-57-87-239.eu-central-1.compute.amazonaws.com/reports/new?
[Sun Sep 25 10:00:20.562283 2016] [:error] [pid 1240:tid 140591274891008] [client 88.190.58.150:49725]   File "/usr/lib/python2.7/dist-packages/sqlalchemy/orm/unitofwork.py", line 372, in execute, referer: http://ec2-52-57-87-239.eu-central-1.compute.amazonaws.com/reports/new?
[Sun Sep 25 10:00:20.562421 2016] [:error] [pid 1240:tid 140591274891008] [client 88.190.58.150:49725]     rec.execute(self), referer: http://ec2-52-57-87-239.eu-central-1.compute.amazonaws.com/reports/new?
[Sun Sep 25 10:00:20.562432 2016] [:error] [pid 1240:tid 140591274891008] [client 88.190.58.150:49725]   File "/usr/lib/python2.7/dist-packages/sqlalchemy/orm/unitofwork.py", line 525, in execute, referer: http://ec2-52-57-87-239.eu-central-1.compute.amazonaws.com/reports/new?
[Sun Sep 25 10:00:20.562443 2016] [:error] [pid 1240:tid 140591274891008] [client 88.190.58.150:49725]     uow, referer: http://ec2-52-57-87-239.eu-central-1.compute.amazonaws.com/reports/new?
[Sun Sep 25 10:00:20.562449 2016] [:error] [pid 1240:tid 140591274891008] [client 88.190.58.150:49725]   File "/usr/lib/python2.7/dist-packages/sqlalchemy/orm/persistence.py", line 64, in save_obj, referer: http://ec2-52-57-87-239.eu-central-1.compute.amazonaws.com/reports/new?
[Sun Sep 25 10:00:20.562656 2016] [:error] [pid 1240:tid 140591274891008] [client 88.190.58.150:49725]     table, insert), referer: http://ec2-52-57-87-239.eu-central-1.compute.amazonaws.com/reports/new?
[Sun Sep 25 10:00:20.562667 2016] [:error] [pid 1240:tid 140591274891008] [client 88.190.58.150:49725]   File "/usr/lib/python2.7/dist-packages/sqlalchemy/orm/persistence.py", line 569, in _emit_insert_statements, referer: http://ec2-52-57-87-239.eu-central-1.compute.amazonaws.com/reports/new?
[Sun Sep 25 10:00:20.562678 2016] [:error] [pid 1240:tid 140591274891008] [client 88.190.58.150:49725]     execute(statement, params), referer: http://ec2-52-57-87-239.eu-central-1.compute.amazonaws.com/reports/new?
[Sun Sep 25 10:00:20.562684 2016] [:error] [pid 1240:tid 140591274891008] [client 88.190.58.150:49725]   File "/usr/lib/python2.7/dist-packages/sqlalchemy/engine/base.py", line 662, in execute, referer: http://ec2-52-57-87-239.eu-central-1.compute.amazonaws.com/reports/new?
[Sun Sep 25 10:00:20.563004 2016] [:error] [pid 1240:tid 140591274891008] [client 88.190.58.150:49725]     params), referer: http://ec2-52-57-87-239.eu-central-1.compute.amazonaws.com/reports/new?
[Sun Sep 25 10:00:20.563015 2016] [:error] [pid 1240:tid 140591274891008] [client 88.190.58.150:49725]   File "/usr/lib/python2.7/dist-packages/sqlalchemy/engine/base.py", line 761, in _execute_clauseelement, referer: http://ec2-52-57-87-239.eu-central-1.compute.amazonaws.com/reports/new?
[Sun Sep 25 10:00:20.563031 2016] [:error] [pid 1240:tid 140591274891008] [client 88.190.58.150:49725]     compiled_sql, distilled_params, referer: http://ec2-52-57-87-239.eu-central-1.compute.amazonaws.com/reports/new?
[Sun Sep 25 10:00:20.563038 2016] [:error] [pid 1240:tid 140591274891008] [client 88.190.58.150:49725]   File "/usr/lib/python2.7/dist-packages/sqlalchemy/engine/base.py", line 874, in _execute_context, referer: http://ec2-52-57-87-239.eu-central-1.compute.amazonaws.com/reports/new?
[Sun Sep 25 10:00:20.563046 2016] [:error] [pid 1240:tid 140591274891008] [client 88.190.58.150:49725]     context), referer: http://ec2-52-57-87-239.eu-central-1.compute.amazonaws.com/reports/new?
[Sun Sep 25 10:00:20.563051 2016] [:error] [pid 1240:tid 140591274891008] [client 88.190.58.150:49725]   File "/usr/lib/python2.7/dist-packages/sqlalchemy/engine/base.py", line 1024, in _handle_dbapi_exception, referer: http://ec2-52-57-87-239.eu-central-1.compute.amazonaws.com/reports/new?
[Sun Sep 25 10:00:20.563059 2016] [:error] [pid 1240:tid 140591274891008] [client 88.190.58.150:49725]     exc_info, referer: http://ec2-52-57-87-239.eu-central-1.compute.amazonaws.com/reports/new?
[Sun Sep 25 10:00:20.563064 2016] [:error] [pid 1240:tid 140591274891008] [client 88.190.58.150:49725]   File "/usr/lib/python2.7/dist-packages/sqlalchemy/util/compat.py", line 196, in raise_from_cause, referer: http://ec2-52-57-87-239.eu-central-1.compute.amazonaws.com/reports/new?
[Sun Sep 25 10:00:20.563113 2016] [:error] [pid 1240:tid 140591274891008] [client 88.190.58.150:49725]     reraise(type(exception), exception, tb=exc_tb), referer: http://ec2-52-57-87-239.eu-central-1.compute.amazonaws.com/reports/new?
[Sun Sep 25 10:00:20.563121 2016] [:error] [pid 1240:tid 140591274891008] [client 88.190.58.150:49725]   File "/usr/lib/python2.7/dist-packages/sqlalchemy/engine/base.py", line 867, in _execute_context, referer: http://ec2-52-57-87-239.eu-central-1.compute.amazonaws.com/reports/new?
[Sun Sep 25 10:00:20.563130 2016] [:error] [pid 1240:tid 140591274891008] [client 88.190.58.150:49725]     context), referer: http://ec2-52-57-87-239.eu-central-1.compute.amazonaws.com/reports/new?
[Sun Sep 25 10:00:20.563136 2016] [:error] [pid 1240:tid 140591274891008] [client 88.190.58.150:49725]   File "/usr/lib/python2.7/dist-packages/sqlalchemy/engine/default.py", line 324, in do_execute, referer: http://ec2-52-57-87-239.eu-central-1.compute.amazonaws.com/reports/new?
[Sun Sep 25 10:00:20.563340 2016] [:error] [pid 1240:tid 140591274891008] [client 88.190.58.150:49725]     cursor.execute(statement, parameters), referer: http://ec2-52-57-87-239.eu-central-1.compute.amazonaws.com/reports/new?
[Sun Sep 25 10:00:20.563407 2016] [:error] [pid 1240:tid 140591274891008] [client 88.190.58.150:49725] DataError: (DataError) invalid input syntax for integer: "ffffqsfqsfqs", referer: http://ec2-52-57-87-239.eu-central-1.compute.amazonaws.com/reports/new?
[Sun Sep 25 10:00:20.563412 2016] [:error] [pid 1240:tid 140591274891008] [client 88.190.58.150:49725] LINE 1: ... '', '', '0000000', 'gaylord.marville@gmail.com', 'ffffqsfqs..., referer: http://ec2-52-57-87-239.eu-central-1.compute.amazonaws.com/reports/new?
[Sun Sep 25 10:00:20.563415 2016] [:error] [pid 1240:tid 140591274891008] [client 88.190.58.150:49725]                                                              ^, referer: http://ec2-52-57-87-239.eu-central-1.compute.amazonaws.com/reports/new?
[Sun Sep 25 10:00:20.563419 2016] [:error] [pid 1240:tid 140591274891008] [client 88.190.58.150:49725]  'INSERT INTO report (site_name, site_full_adress, site_adress_number, site_adress_street, site_adress_postcode, site_adress_city, site_administrative_area, site_adress_country, "site_ERPcategory", "site_ERPtype", client_lastname, client_firstname, client_full_adress, client_adress_number, client_adress_street, client_adress_postcode, client_adress_city, client_administrative_area, client_adress_country, client_phone, client_mail, report_number, "report_visitDate", "report_redactionDate", report_picture, "report_pictureOrientation", editor_lastname, editor_firstname, editor_full_adress, editor_adress_number, editor_adress_street, editor_adress_postcode, editor_adress_city, editor_administrative_area, editor_adress_country, editor_phone, editor_mail, frame_choice, user_id) VALUES (%(site_name)s, %(site_full_adress)s, %(site_adress_number)s, %(site_adress_street)s, %(site_adress_postcode)s, %(site_adress_city)s, %(site_administrative_area)s, %(site_adress_country)s, %(site_ERPcategory)s, %(site_ERPtype)s, %(client_lastname)s, %(client_firstname)s, %(client_full_adress)s, %(client_adress_number)s, %(client_adress_street)s, %(client_adress_postcode)s, %(client_adress_city)s, %(client_administrative_area)s, %(client_adress_country)s, %(client_phone)s, %(client_mail)s, %(report_number)s, %(report_visitDate)s, %(report_redactionDate)s, %(report_picture)s, %(report_pictureOrientation)s, %(editor_lastname)s, %(editor_firstname)s, %(editor_full_adress)s, %(editor_adress_number)s, %(editor_adress_street)s, %(editor_adress_postcode)s, %(editor_adress_city)s, %(editor_administrative_area)s, %(editor_adress_country)s, %(editor_phone)s, %(editor_mail)s, %(frame_choice)s, %(user_id)s) RETURNING report.id' {'site_name': u'fqsfqsf', 'report_number': u'ffffqsfqsfqs', 'editor_full_adress': u'sdfsdfsdf', 'editor_adress_street': u'', 'client_lastname': u'sdfsfddsf', 'site_ERPtype': u'D', 'editor_adress_city': u'', 'client_phone': u'0000000', 'editor_administrative_area': u'', 'client_firstname': u'dfsdfsdfsdf', 'user_id': 3, 'site_adress_postcode': u'', 'client_full_adress': u'fdsfsdfsds', 'report_visitDate': u'2016-09-22', 'report_redactionDate': u'2016-09-22', 'client_adress_city': u'', 'site_adress_number': u'', 'client_adress_country': u'', 'editor_adress_postcode': u'', 'client_adress_number': u'', 'client_mail': u'gaylord.marville@gmail.com', 'editor_phone': u'0000000', 'site_adress_city': u'', 'editor_adress_number': u'', 'editor_adress_country': u'', 'site_full_adress': u'qfdqsfsfsq', 'site_administrative_area': u'', 'report_pictureOrientation': 'None', 'editor_mail': u'gaylord.marville@gmail.com', 'report_picture': 'undefined.jpg', 'client_administrative_area': u'', 'client_adress_postcode': u'', 'site_ERPcategory': u'2', 'editor_lastname': u'sdfsdfsd', 'site_adress_street': u'', 'site_adress_country': u'', 'client_adress_street': u'', 'editor_firstname': u'fsdfsdfsdfds', 'frame_choice': 0}, referer: http://ec2-52-57-87-239.eu-central-1.compute.amazonaws.com/reports/new?
[Sun Sep 25 10:27:23.917855 2016] [:error] [pid 1241:tid 140591300069120] [client 88.190.58.150:49917] mod_wsgi (pid=1241): Exception occurred processing WSGI script '/var/www/myapp.wsgi'., referer: http://ec2-52-57-87-239.eu-central-1.compute.amazonaws.com/reports/new?
[Sun Sep 25 10:27:23.917890 2016] [:error] [pid 1241:tid 140591300069120] [client 88.190.58.150:49917] Traceback (most recent call last):, referer: http://ec2-52-57-87-239.eu-central-1.compute.amazonaws.com/reports/new?
[Sun Sep 25 10:27:23.917906 2016] [:error] [pid 1241:tid 140591300069120] [client 88.190.58.150:49917]   File "/usr/lib/python2.7/dist-packages/flask/app.py", line 1836, in __call__, referer: http://ec2-52-57-87-239.eu-central-1.compute.amazonaws.com/reports/new?
[Sun Sep 25 10:27:23.918335 2016] [:error] [pid 1241:tid 140591300069120] [client 88.190.58.150:49917]     return self.wsgi_app(environ, start_response), referer: http://ec2-52-57-87-239.eu-central-1.compute.amazonaws.com/reports/new?
[Sun Sep 25 10:27:23.918352 2016] [:error] [pid 1241:tid 140591300069120] [client 88.190.58.150:49917]   File "/usr/lib/python2.7/dist-packages/flask/app.py", line 1820, in wsgi_app, referer: http://ec2-52-57-87-239.eu-central-1.compute.amazonaws.com/reports/new?
[Sun Sep 25 10:27:23.918368 2016] [:error] [pid 1241:tid 140591300069120] [client 88.190.58.150:49917]     response = self.make_response(self.handle_exception(e)), referer: http://ec2-52-57-87-239.eu-central-1.compute.amazonaws.com/reports/new?
[Sun Sep 25 10:27:23.918386 2016] [:error] [pid 1241:tid 140591300069120] [client 88.190.58.150:49917]   File "/usr/lib/python2.7/dist-packages/flask/app.py", line 1403, in handle_exception, referer: http://ec2-52-57-87-239.eu-central-1.compute.amazonaws.com/reports/new?
[Sun Sep 25 10:27:23.918396 2016] [:error] [pid 1241:tid 140591300069120] [client 88.190.58.150:49917]     reraise(exc_type, exc_value, tb), referer: http://ec2-52-57-87-239.eu-central-1.compute.amazonaws.com/reports/new?
[Sun Sep 25 10:27:23.918402 2016] [:error] [pid 1241:tid 140591300069120] [client 88.190.58.150:49917]   File "/usr/lib/python2.7/dist-packages/flask/app.py", line 1817, in wsgi_app, referer: http://ec2-52-57-87-239.eu-central-1.compute.amazonaws.com/reports/new?
[Sun Sep 25 10:27:23.918409 2016] [:error] [pid 1241:tid 140591300069120] [client 88.190.58.150:49917]     response = self.full_dispatch_request(), referer: http://ec2-52-57-87-239.eu-central-1.compute.amazonaws.com/reports/new?
[Sun Sep 25 10:27:23.918415 2016] [:error] [pid 1241:tid 140591300069120] [client 88.190.58.150:49917]   File "/usr/lib/python2.7/dist-packages/flask/app.py", line 1477, in full_dispatch_request, referer: http://ec2-52-57-87-239.eu-central-1.compute.amazonaws.com/reports/new?
[Sun Sep 25 10:27:23.918422 2016] [:error] [pid 1241:tid 140591300069120] [client 88.190.58.150:49917]     rv = self.handle_user_exception(e), referer: http://ec2-52-57-87-239.eu-central-1.compute.amazonaws.com/reports/new?
[Sun Sep 25 10:27:23.918427 2016] [:error] [pid 1241:tid 140591300069120] [client 88.190.58.150:49917]   File "/usr/lib/python2.7/dist-packages/flask/app.py", line 1381, in handle_user_exception, referer: http://ec2-52-57-87-239.eu-central-1.compute.amazonaws.com/reports/new?
[Sun Sep 25 10:27:23.918435 2016] [:error] [pid 1241:tid 140591300069120] [client 88.190.58.150:49917]     reraise(exc_type, exc_value, tb), referer: http://ec2-52-57-87-239.eu-central-1.compute.amazonaws.com/reports/new?
[Sun Sep 25 10:27:23.918440 2016] [:error] [pid 1241:tid 140591300069120] [client 88.190.58.150:49917]   File "/usr/lib/python2.7/dist-packages/flask/app.py", line 1475, in full_dispatch_request, referer: http://ec2-52-57-87-239.eu-central-1.compute.amazonaws.com/reports/new?
[Sun Sep 25 10:27:23.918458 2016] [:error] [pid 1241:tid 140591300069120] [client 88.190.58.150:49917]     rv = self.dispatch_request(), referer: http://ec2-52-57-87-239.eu-central-1.compute.amazonaws.com/reports/new?
[Sun Sep 25 10:27:23.918463 2016] [:error] [pid 1241:tid 140591300069120] [client 88.190.58.150:49917]   File "/usr/lib/python2.7/dist-packages/flask/app.py", line 1461, in dispatch_request, referer: http://ec2-52-57-87-239.eu-central-1.compute.amazonaws.com/reports/new?
[Sun Sep 25 10:27:23.918470 2016] [:error] [pid 1241:tid 140591300069120] [client 88.190.58.150:49917]     return self.view_functions[rule.endpoint](**req.view_args), referer: http://ec2-52-57-87-239.eu-central-1.compute.amazonaws.com/reports/new?
[Sun Sep 25 10:27:23.918477 2016] [:error] [pid 1241:tid 140591300069120] [client 88.190.58.150:49917]   File "/var/www/ItemCatalog/finalProject.py", line 69, in decorated_function, referer: http://ec2-52-57-87-239.eu-central-1.compute.amazonaws.com/reports/new?
[Sun Sep 25 10:27:23.918656 2016] [:error] [pid 1241:tid 140591300069120] [client 88.190.58.150:49917]     return f(*args, **kwargs), referer: http://ec2-52-57-87-239.eu-central-1.compute.amazonaws.com/reports/new?
[Sun Sep 25 10:27:23.918667 2016] [:error] [pid 1241:tid 140591300069120] [client 88.190.58.150:49917]   File "/var/www/ItemCatalog/finalProject.py", line 503, in newSingleReport, referer: http://ec2-52-57-87-239.eu-central-1.compute.amazonaws.com/reports/new?
[Sun Sep 25 10:27:23.918678 2016] [:error] [pid 1241:tid 140591300069120] [client 88.190.58.150:49917]     session.commit(), referer: http://ec2-52-57-87-239.eu-central-1.compute.amazonaws.com/reports/new?
[Sun Sep 25 10:27:23.918686 2016] [:error] [pid 1241:tid 140591300069120] [client 88.190.58.150:49917]   File "/usr/lib/python2.7/dist-packages/sqlalchemy/orm/session.py", line 721, in commit, referer: http://ec2-52-57-87-239.eu-central-1.compute.amazonaws.com/reports/new?
[Sun Sep 25 10:27:23.919096 2016] [:error] [pid 1241:tid 140591300069120] [client 88.190.58.150:49917]     self.transaction.commit(), referer: http://ec2-52-57-87-239.eu-central-1.compute.amazonaws.com/reports/new?
[Sun Sep 25 10:27:23.919107 2016] [:error] [pid 1241:tid 140591300069120] [client 88.190.58.150:49917]   File "/usr/lib/python2.7/dist-packages/sqlalchemy/orm/session.py", line 354, in commit, referer: http://ec2-52-57-87-239.eu-central-1.compute.amazonaws.com/reports/new?
[Sun Sep 25 10:27:23.919119 2016] [:error] [pid 1241:tid 140591300069120] [client 88.190.58.150:49917]     self._prepare_impl(), referer: http://ec2-52-57-87-239.eu-central-1.compute.amazonaws.com/reports/new?
[Sun Sep 25 10:27:23.919125 2016] [:error] [pid 1241:tid 140591300069120] [client 88.190.58.150:49917]   File "/usr/lib/python2.7/dist-packages/sqlalchemy/orm/session.py", line 334, in _prepare_impl, referer: http://ec2-52-57-87-239.eu-central-1.compute.amazonaws.com/reports/new?
[Sun Sep 25 10:27:23.919133 2016] [:error] [pid 1241:tid 140591300069120] [client 88.190.58.150:49917]     self.session.flush(), referer: http://ec2-52-57-87-239.eu-central-1.compute.amazonaws.com/reports/new?
[Sun Sep 25 10:27:23.919140 2016] [:error] [pid 1241:tid 140591300069120] [client 88.190.58.150:49917]   File "/usr/lib/python2.7/dist-packages/sqlalchemy/orm/session.py", line 1818, in flush, referer: http://ec2-52-57-87-239.eu-central-1.compute.amazonaws.com/reports/new?
[Sun Sep 25 10:27:23.919148 2016] [:error] [pid 1241:tid 140591300069120] [client 88.190.58.150:49917]     self._flush(objects), referer: http://ec2-52-57-87-239.eu-central-1.compute.amazonaws.com/reports/new?
[Sun Sep 25 10:27:23.919153 2016] [:error] [pid 1241:tid 140591300069120] [client 88.190.58.150:49917]   File "/usr/lib/python2.7/dist-packages/sqlalchemy/orm/session.py", line 1936, in _flush, referer: http://ec2-52-57-87-239.eu-central-1.compute.amazonaws.com/reports/new?
[Sun Sep 25 10:27:23.919160 2016] [:error] [pid 1241:tid 140591300069120] [client 88.190.58.150:49917]     transaction.rollback(_capture_exception=True), referer: http://ec2-52-57-87-239.eu-central-1.compute.amazonaws.com/reports/new?
[Sun Sep 25 10:27:23.919216 2016] [:error] [pid 1241:tid 140591300069120] [client 88.190.58.150:49917]   File "/usr/lib/python2.7/dist-packages/sqlalchemy/util/langhelpers.py", line 58, in __exit__, referer: http://ec2-52-57-87-239.eu-central-1.compute.amazonaws.com/reports/new?
[Sun Sep 25 10:27:23.919439 2016] [:error] [pid 1241:tid 140591300069120] [client 88.190.58.150:49917]     compat.reraise(exc_type, exc_value, exc_tb), referer: http://ec2-52-57-87-239.eu-central-1.compute.amazonaws.com/reports/new?
[Sun Sep 25 10:27:23.919450 2016] [:error] [pid 1241:tid 140591300069120] [client 88.190.58.150:49917]   File "/usr/lib/python2.7/dist-packages/sqlalchemy/orm/session.py", line 1900, in _flush, referer: http://ec2-52-57-87-239.eu-central-1.compute.amazonaws.com/reports/new?
[Sun Sep 25 10:27:23.919461 2016] [:error] [pid 1241:tid 140591300069120] [client 88.190.58.150:49917]     flush_context.execute(), referer: http://ec2-52-57-87-239.eu-central-1.compute.amazonaws.com/reports/new?
[Sun Sep 25 10:27:23.919468 2016] [:error] [pid 1241:tid 140591300069120] [client 88.190.58.150:49917]   File "/usr/lib/python2.7/dist-packages/sqlalchemy/orm/unitofwork.py", line 372, in execute, referer: http://ec2-52-57-87-239.eu-central-1.compute.amazonaws.com/reports/new?
[Sun Sep 25 10:27:23.919597 2016] [:error] [pid 1241:tid 140591300069120] [client 88.190.58.150:49917]     rec.execute(self), referer: http://ec2-52-57-87-239.eu-central-1.compute.amazonaws.com/reports/new?
[Sun Sep 25 10:27:23.919608 2016] [:error] [pid 1241:tid 140591300069120] [client 88.190.58.150:49917]   File "/usr/lib/python2.7/dist-packages/sqlalchemy/orm/unitofwork.py", line 525, in execute, referer: http://ec2-52-57-87-239.eu-central-1.compute.amazonaws.com/reports/new?
[Sun Sep 25 10:27:23.919625 2016] [:error] [pid 1241:tid 140591300069120] [client 88.190.58.150:49917]     uow, referer: http://ec2-52-57-87-239.eu-central-1.compute.amazonaws.com/reports/new?
[Sun Sep 25 10:27:23.919632 2016] [:error] [pid 1241:tid 140591300069120] [client 88.190.58.150:49917]   File "/usr/lib/python2.7/dist-packages/sqlalchemy/orm/persistence.py", line 64, in save_obj, referer: http://ec2-52-57-87-239.eu-central-1.compute.amazonaws.com/reports/new?
[Sun Sep 25 10:27:23.919823 2016] [:error] [pid 1241:tid 140591300069120] [client 88.190.58.150:49917]     table, insert), referer: http://ec2-52-57-87-239.eu-central-1.compute.amazonaws.com/reports/new?
[Sun Sep 25 10:27:23.919846 2016] [:error] [pid 1241:tid 140591300069120] [client 88.190.58.150:49917]   File "/usr/lib/python2.7/dist-packages/sqlalchemy/orm/persistence.py", line 569, in _emit_insert_statements, referer: http://ec2-52-57-87-239.eu-central-1.compute.amazonaws.com/reports/new?
[Sun Sep 25 10:27:23.919856 2016] [:error] [pid 1241:tid 140591300069120] [client 88.190.58.150:49917]     execute(statement, params), referer: http://ec2-52-57-87-239.eu-central-1.compute.amazonaws.com/reports/new?
[Sun Sep 25 10:27:23.919875 2016] [:error] [pid 1241:tid 140591300069120] [client 88.190.58.150:49917]   File "/usr/lib/python2.7/dist-packages/sqlalchemy/engine/base.py", line 662, in execute, referer: http://ec2-52-57-87-239.eu-central-1.compute.amazonaws.com/reports/new?
[Sun Sep 25 10:27:23.920176 2016] [:error] [pid 1241:tid 140591300069120] [client 88.190.58.150:49917]     params), referer: http://ec2-52-57-87-239.eu-central-1.compute.amazonaws.com/reports/new?
[Sun Sep 25 10:27:23.920188 2016] [:error] [pid 1241:tid 140591300069120] [client 88.190.58.150:49917]   File "/usr/lib/python2.7/dist-packages/sqlalchemy/engine/base.py", line 761, in _execute_clauseelement, referer: http://ec2-52-57-87-239.eu-central-1.compute.amazonaws.com/reports/new?
[Sun Sep 25 10:27:23.920199 2016] [:error] [pid 1241:tid 140591300069120] [client 88.190.58.150:49917]     compiled_sql, distilled_params, referer: http://ec2-52-57-87-239.eu-central-1.compute.amazonaws.com/reports/new?
[Sun Sep 25 10:27:23.920204 2016] [:error] [pid 1241:tid 140591300069120] [client 88.190.58.150:49917]   File "/usr/lib/python2.7/dist-packages/sqlalchemy/engine/base.py", line 874, in _execute_context, referer: http://ec2-52-57-87-239.eu-central-1.compute.amazonaws.com/reports/new?
[Sun Sep 25 10:27:23.920211 2016] [:error] [pid 1241:tid 140591300069120] [client 88.190.58.150:49917]     context), referer: http://ec2-52-57-87-239.eu-central-1.compute.amazonaws.com/reports/new?
[Sun Sep 25 10:27:23.920216 2016] [:error] [pid 1241:tid 140591300069120] [client 88.190.58.150:49917]   File "/usr/lib/python2.7/dist-packages/sqlalchemy/engine/base.py", line 1024, in _handle_dbapi_exception, referer: http://ec2-52-57-87-239.eu-central-1.compute.amazonaws.com/reports/new?
[Sun Sep 25 10:27:23.920223 2016] [:error] [pid 1241:tid 140591300069120] [client 88.190.58.150:49917]     exc_info, referer: http://ec2-52-57-87-239.eu-central-1.compute.amazonaws.com/reports/new?
[Sun Sep 25 10:27:23.920229 2016] [:error] [pid 1241:tid 140591300069120] [client 88.190.58.150:49917]   File "/usr/lib/python2.7/dist-packages/sqlalchemy/util/compat.py", line 196, in raise_from_cause, referer: http://ec2-52-57-87-239.eu-central-1.compute.amazonaws.com/reports/new?
[Sun Sep 25 10:27:23.920274 2016] [:error] [pid 1241:tid 140591300069120] [client 88.190.58.150:49917]     reraise(type(exception), exception, tb=exc_tb), referer: http://ec2-52-57-87-239.eu-central-1.compute.amazonaws.com/reports/new?
[Sun Sep 25 10:27:23.920282 2016] [:error] [pid 1241:tid 140591300069120] [client 88.190.58.150:49917]   File "/usr/lib/python2.7/dist-packages/sqlalchemy/engine/base.py", line 867, in _execute_context, referer: http://ec2-52-57-87-239.eu-central-1.compute.amazonaws.com/reports/new?
[Sun Sep 25 10:27:23.920290 2016] [:error] [pid 1241:tid 140591300069120] [client 88.190.58.150:49917]     context), referer: http://ec2-52-57-87-239.eu-central-1.compute.amazonaws.com/reports/new?
[Sun Sep 25 10:27:23.920301 2016] [:error] [pid 1241:tid 140591300069120] [client 88.190.58.150:49917]   File "/usr/lib/python2.7/dist-packages/sqlalchemy/engine/default.py", line 324, in do_execute, referer: http://ec2-52-57-87-239.eu-central-1.compute.amazonaws.com/reports/new?
[Sun Sep 25 10:27:23.920448 2016] [:error] [pid 1241:tid 140591300069120] [client 88.190.58.150:49917]     cursor.execute(statement, parameters), referer: http://ec2-52-57-87-239.eu-central-1.compute.amazonaws.com/reports/new?
[Sun Sep 25 10:27:23.920516 2016] [:error] [pid 1241:tid 140591300069120] [client 88.190.58.150:49917] IntegrityError: (IntegrityError) insert or update on table "report" violates foreign key constraint "report_frame_choice_fkey", referer: http://ec2-52-57-87-239.eu-central-1.compute.amazonaws.com/reports/new?
[Sun Sep 25 10:27:23.920522 2016] [:error] [pid 1241:tid 140591300069120] [client 88.190.58.150:49917] DETAIL:  Key (frame_choice)=(0) is not present in table "frame"., referer: http://ec2-52-57-87-239.eu-central-1.compute.amazonaws.com/reports/new?
[Sun Sep 25 10:27:23.920526 2016] [:error] [pid 1241:tid 140591300069120] [client 88.190.58.150:49917]  'INSERT INTO report (site_name, site_full_adress, site_adress_number, site_adress_street, site_adress_postcode, site_adress_city, site_administrative_area, site_adress_country, "site_ERPcategory", "site_ERPtype", client_lastname, client_firstname, client_full_adress, client_adress_number, client_adress_street, client_adress_postcode, client_adress_city, client_administrative_area, client_adress_country, client_phone, client_mail, report_number, "report_visitDate", "report_redactionDate", report_picture, "report_pictureOrientation", editor_lastname, editor_firstname, editor_full_adress, editor_adress_number, editor_adress_street, editor_adress_postcode, editor_adress_city, editor_administrative_area, editor_adress_country, editor_phone, editor_mail, frame_choice, user_id) VALUES (%(site_name)s, %(site_full_adress)s, %(site_adress_number)s, %(site_adress_street)s, %(site_adress_postcode)s, %(site_adress_city)s, %(site_administrative_area)s, %(site_adress_country)s, %(site_ERPcategory)s, %(site_ERPtype)s, %(client_lastname)s, %(client_firstname)s, %(client_full_adress)s, %(client_adress_number)s, %(client_adress_street)s, %(client_adress_postcode)s, %(client_adress_city)s, %(client_administrative_area)s, %(client_adress_country)s, %(client_phone)s, %(client_mail)s, %(report_number)s, %(report_visitDate)s, %(report_redactionDate)s, %(report_picture)s, %(report_pictureOrientation)s, %(editor_lastname)s, %(editor_firstname)s, %(editor_full_adress)s, %(editor_adress_number)s, %(editor_adress_street)s, %(editor_adress_postcode)s, %(editor_adress_city)s, %(editor_administrative_area)s, %(editor_adress_country)s, %(editor_phone)s, %(editor_mail)s, %(frame_choice)s, %(user_id)s) RETURNING report.id' {'site_name': u'kjkjhkjh', 'report_number': u'09876', 'editor_full_adress': u'gj', 'editor_adress_street': u'', 'client_lastname': u'gsdgsdgds', 'site_ERPtype': u'N', 'editor_adress_city': u'', 'client_phone': u'dgsdgsdgdsgds', 'editor_administrative_area': u'', 'client_firstname': u'ddsdsgsd', 'user_id': 3, 'site_full_adress': u'hjkhhhhkh', 'client_full_adress': u'gsdgsdgdsg', 'report_visitDate': u'2016-09-16', 'report_redactionDate': u'2016-09-29', 'client_adress_city': u'', 'site_adress_number': u'', 'client_adress_country': u'', 'editor_adress_postcode': u'', 'client_adress_number': u'', 'client_mail': u'sdgsdgdsg@sdfsd.fr', 'editor_phone': u'jhg', 'editor_mail': u'sdgsdgdsg@sdfsd.fr', 'editor_adress_number': u'', 'editor_adress_country': u'', 'site_adress_postcode': u'', 'site_administrative_area': u'', 'report_pictureOrientation': 'None', 'site_adress_city': u'', 'report_picture': 'undefined.jpg', 'client_administrative_area': u'', 'client_adress_postcode': u'', 'site_ERPcategory': u'4', 'editor_lastname': u'jh', 'site_adress_street': u'', 'site_adress_country': u'', 'client_adress_street': u'', 'editor_firstname': u'sfsfgg', 'frame_choice': 0}, referer: http://ec2-52-57-87-239.eu-central-1.compute.amazonaws.com/reports/new?
[Sun Sep 25 10:28:54.725733 2016] [:error] [pid 1240:tid 140591149000448] [client 88.190.58.150:49929] mod_wsgi (pid=1240): Exception occurred processing WSGI script '/var/www/myapp.wsgi'., referer: http://ec2-52-57-87-239.eu-central-1.compute.amazonaws.com/
[Sun Sep 25 10:28:54.726967 2016] [:error] [pid 1240:tid 140591149000448] [client 88.190.58.150:49929] Traceback (most recent call last):, referer: http://ec2-52-57-87-239.eu-central-1.compute.amazonaws.com/
[Sun Sep 25 10:28:54.727004 2016] [:error] [pid 1240:tid 140591149000448] [client 88.190.58.150:49929]   File "/usr/lib/python2.7/dist-packages/flask/app.py", line 1836, in __call__, referer: http://ec2-52-57-87-239.eu-central-1.compute.amazonaws.com/
[Sun Sep 25 10:28:54.727043 2016] [:error] [pid 1240:tid 140591149000448] [client 88.190.58.150:49929]     return self.wsgi_app(environ, start_response), referer: http://ec2-52-57-87-239.eu-central-1.compute.amazonaws.com/
[Sun Sep 25 10:28:54.727058 2016] [:error] [pid 1240:tid 140591149000448] [client 88.190.58.150:49929]   File "/usr/lib/python2.7/dist-packages/flask/app.py", line 1820, in wsgi_app, referer: http://ec2-52-57-87-239.eu-central-1.compute.amazonaws.com/
[Sun Sep 25 10:28:54.727085 2016] [:error] [pid 1240:tid 140591149000448] [client 88.190.58.150:49929]     response = self.make_response(self.handle_exception(e)), referer: http://ec2-52-57-87-239.eu-central-1.compute.amazonaws.com/
[Sun Sep 25 10:28:54.727091 2016] [:error] [pid 1240:tid 140591149000448] [client 88.190.58.150:49929]   File "/usr/lib/python2.7/dist-packages/flask/app.py", line 1403, in handle_exception, referer: http://ec2-52-57-87-239.eu-central-1.compute.amazonaws.com/
[Sun Sep 25 10:28:54.727099 2016] [:error] [pid 1240:tid 140591149000448] [client 88.190.58.150:49929]     reraise(exc_type, exc_value, tb), referer: http://ec2-52-57-87-239.eu-central-1.compute.amazonaws.com/
[Sun Sep 25 10:28:54.727108 2016] [:error] [pid 1240:tid 140591149000448] [client 88.190.58.150:49929]   File "/usr/lib/python2.7/dist-packages/flask/app.py", line 1817, in wsgi_app, referer: http://ec2-52-57-87-239.eu-central-1.compute.amazonaws.com/
[Sun Sep 25 10:28:54.727117 2016] [:error] [pid 1240:tid 140591149000448] [client 88.190.58.150:49929]     response = self.full_dispatch_request(), referer: http://ec2-52-57-87-239.eu-central-1.compute.amazonaws.com/
[Sun Sep 25 10:28:54.727122 2016] [:error] [pid 1240:tid 140591149000448] [client 88.190.58.150:49929]   File "/usr/lib/python2.7/dist-packages/flask/app.py", line 1477, in full_dispatch_request, referer: http://ec2-52-57-87-239.eu-central-1.compute.amazonaws.com/
[Sun Sep 25 10:28:54.727130 2016] [:error] [pid 1240:tid 140591149000448] [client 88.190.58.150:49929]     rv = self.handle_user_exception(e), referer: http://ec2-52-57-87-239.eu-central-1.compute.amazonaws.com/
[Sun Sep 25 10:28:54.727135 2016] [:error] [pid 1240:tid 140591149000448] [client 88.190.58.150:49929]   File "/usr/lib/python2.7/dist-packages/flask/app.py", line 1381, in handle_user_exception, referer: http://ec2-52-57-87-239.eu-central-1.compute.amazonaws.com/
[Sun Sep 25 10:28:54.727156 2016] [:error] [pid 1240:tid 140591149000448] [client 88.190.58.150:49929]     reraise(exc_type, exc_value, tb), referer: http://ec2-52-57-87-239.eu-central-1.compute.amazonaws.com/
[Sun Sep 25 10:28:54.727160 2016] [:error] [pid 1240:tid 140591149000448] [client 88.190.58.150:49929]   File "/usr/lib/python2.7/dist-packages/flask/app.py", line 1475, in full_dispatch_request, referer: http://ec2-52-57-87-239.eu-central-1.compute.amazonaws.com/
[Sun Sep 25 10:28:54.727199 2016] [:error] [pid 1240:tid 140591149000448] [client 88.190.58.150:49929]     rv = self.dispatch_request(), referer: http://ec2-52-57-87-239.eu-central-1.compute.amazonaws.com/
[Sun Sep 25 10:28:54.727208 2016] [:error] [pid 1240:tid 140591149000448] [client 88.190.58.150:49929]   File "/usr/lib/python2.7/dist-packages/flask/app.py", line 1461, in dispatch_request, referer: http://ec2-52-57-87-239.eu-central-1.compute.amazonaws.com/
[Sun Sep 25 10:28:54.727225 2016] [:error] [pid 1240:tid 140591149000448] [client 88.190.58.150:49929]     return self.view_functions[rule.endpoint](**req.view_args), referer: http://ec2-52-57-87-239.eu-central-1.compute.amazonaws.com/
[Sun Sep 25 10:28:54.727230 2016] [:error] [pid 1240:tid 140591149000448] [client 88.190.58.150:49929]   File "/var/www/ItemCatalog/finalProject.py", line 69, in decorated_function, referer: http://ec2-52-57-87-239.eu-central-1.compute.amazonaws.com/
[Sun Sep 25 10:28:54.727238 2016] [:error] [pid 1240:tid 140591149000448] [client 88.190.58.150:49929]     return f(*args, **kwargs), referer: http://ec2-52-57-87-239.eu-central-1.compute.amazonaws.com/
[Sun Sep 25 10:28:54.727243 2016] [:error] [pid 1240:tid 140591149000448] [client 88.190.58.150:49929]   File "/var/www/ItemCatalog/finalProject.py", line 524, in newSingleReport, referer: http://ec2-52-57-87-239.eu-central-1.compute.amazonaws.com/
[Sun Sep 25 10:28:54.727250 2016] [:error] [pid 1240:tid 140591149000448] [client 88.190.58.150:49929]     user=login_session), referer: http://ec2-52-57-87-239.eu-central-1.compute.amazonaws.com/
[Sun Sep 25 10:28:54.727255 2016] [:error] [pid 1240:tid 140591149000448] [client 88.190.58.150:49929]   File "/usr/lib/python2.7/dist-packages/flask/templating.py", line 128, in render_template, referer: http://ec2-52-57-87-239.eu-central-1.compute.amazonaws.com/
[Sun Sep 25 10:28:54.749020 2016] [:error] [pid 1240:tid 140591149000448] [client 88.190.58.150:49929]     context, ctx.app), referer: http://ec2-52-57-87-239.eu-central-1.compute.amazonaws.com/
[Sun Sep 25 10:28:54.749050 2016] [:error] [pid 1240:tid 140591149000448] [client 88.190.58.150:49929]   File "/usr/lib/python2.7/dist-packages/flask/templating.py", line 110, in _render, referer: http://ec2-52-57-87-239.eu-central-1.compute.amazonaws.com/
[Sun Sep 25 10:28:54.749079 2016] [:error] [pid 1240:tid 140591149000448] [client 88.190.58.150:49929]     rv = template.render(context), referer: http://ec2-52-57-87-239.eu-central-1.compute.amazonaws.com/
[Sun Sep 25 10:28:54.749091 2016] [:error] [pid 1240:tid 140591149000448] [client 88.190.58.150:49929]   File "/usr/lib/python2.7/dist-packages/jinja2/environment.py", line 969, in render, referer: http://ec2-52-57-87-239.eu-central-1.compute.amazonaws.com/
[Sun Sep 25 10:28:54.750947 2016] [:error] [pid 1240:tid 140591149000448] [client 88.190.58.150:49929]     return self.environment.handle_exception(exc_info, True), referer: http://ec2-52-57-87-239.eu-central-1.compute.amazonaws.com/
[Sun Sep 25 10:28:54.750959 2016] [:error] [pid 1240:tid 140591149000448] [client 88.190.58.150:49929]   File "/usr/lib/python2.7/dist-packages/jinja2/environment.py", line 742, in handle_exception, referer: http://ec2-52-57-87-239.eu-central-1.compute.amazonaws.com/
[Sun Sep 25 10:28:54.750971 2016] [:error] [pid 1240:tid 140591149000448] [client 88.190.58.150:49929]     reraise(exc_type, exc_value, tb), referer: http://ec2-52-57-87-239.eu-central-1.compute.amazonaws.com/
[Sun Sep 25 10:28:54.750976 2016] [:error] [pid 1240:tid 140591149000448] [client 88.190.58.150:49929]   File "/var/www/ItemCatalog/templates/createsinglereport.html", line 86, in top-level template code, referer: http://ec2-52-57-87-239.eu-central-1.compute.amazonaws.com/
[Sun Sep 25 10:28:54.751084 2016] [:error] [pid 1240:tid 140591149000448] [client 88.190.58.150:49929]     {% for i in frames %}, referer: http://ec2-52-57-87-239.eu-central-1.compute.amazonaws.com/
[Sun Sep 25 10:28:54.751094 2016] [:error] [pid 1240:tid 140591149000448] [client 88.190.58.150:49929]   File "/usr/lib/python2.7/dist-packages/sqlalchemy/orm/query.py", line 2353, in __iter__, referer: http://ec2-52-57-87-239.eu-central-1.compute.amazonaws.com/
[Sun Sep 25 10:28:54.756528 2016] [:error] [pid 1240:tid 140591149000448] [client 88.190.58.150:49929]     return self._execute_and_instances(context), referer: http://ec2-52-57-87-239.eu-central-1.compute.amazonaws.com/
[Sun Sep 25 10:28:54.756546 2016] [:error] [pid 1240:tid 140591149000448] [client 88.190.58.150:49929]   File "/usr/lib/python2.7/dist-packages/sqlalchemy/orm/query.py", line 2366, in _execute_and_instances, referer: http://ec2-52-57-87-239.eu-central-1.compute.amazonaws.com/
[Sun Sep 25 10:28:54.756560 2016] [:error] [pid 1240:tid 140591149000448] [client 88.190.58.150:49929]     close_with_result=True), referer: http://ec2-52-57-87-239.eu-central-1.compute.amazonaws.com/
[Sun Sep 25 10:28:54.756566 2016] [:error] [pid 1240:tid 140591149000448] [client 88.190.58.150:49929]   File "/usr/lib/python2.7/dist-packages/sqlalchemy/orm/query.py", line 2357, in _connection_from_session, referer: http://ec2-52-57-87-239.eu-central-1.compute.amazonaws.com/
[Sun Sep 25 10:28:54.756574 2016] [:error] [pid 1240:tid 140591149000448] [client 88.190.58.150:49929]     **kw), referer: http://ec2-52-57-87-239.eu-central-1.compute.amazonaws.com/
[Sun Sep 25 10:28:54.756578 2016] [:error] [pid 1240:tid 140591149000448] [client 88.190.58.150:49929]   File "/usr/lib/python2.7/dist-packages/sqlalchemy/orm/session.py", line 799, in connection, referer: http://ec2-52-57-87-239.eu-central-1.compute.amazonaws.com/
[Sun Sep 25 10:28:54.756587 2016] [:error] [pid 1240:tid 140591149000448] [client 88.190.58.150:49929]     close_with_result=close_with_result), referer: http://ec2-52-57-87-239.eu-central-1.compute.amazonaws.com/
[Sun Sep 25 10:28:54.756591 2016] [:error] [pid 1240:tid 140591149000448] [client 88.190.58.150:49929]   File "/usr/lib/python2.7/dist-packages/sqlalchemy/orm/session.py", line 803, in _connection_for_bind, referer: http://ec2-52-57-87-239.eu-central-1.compute.amazonaws.com/
[Sun Sep 25 10:28:54.756598 2016] [:error] [pid 1240:tid 140591149000448] [client 88.190.58.150:49929]     return self.transaction._connection_for_bind(engine), referer: http://ec2-52-57-87-239.eu-central-1.compute.amazonaws.com/
[Sun Sep 25 10:28:54.756603 2016] [:error] [pid 1240:tid 140591149000448] [client 88.190.58.150:49929]   File "/usr/lib/python2.7/dist-packages/sqlalchemy/orm/session.py", line 282, in _connection_for_bind, referer: http://ec2-52-57-87-239.eu-central-1.compute.amazonaws.com/
[Sun Sep 25 10:28:54.756610 2016] [:error] [pid 1240:tid 140591149000448] [client 88.190.58.150:49929]     self._assert_active(), referer: http://ec2-52-57-87-239.eu-central-1.compute.amazonaws.com/
[Sun Sep 25 10:28:54.756614 2016] [:error] [pid 1240:tid 140591149000448] [client 88.190.58.150:49929]   File "/usr/lib/python2.7/dist-packages/sqlalchemy/orm/session.py", line 194, in _assert_active, referer: http://ec2-52-57-87-239.eu-central-1.compute.amazonaws.com/
[Sun Sep 25 10:28:54.756621 2016] [:error] [pid 1240:tid 140591149000448] [client 88.190.58.150:49929]     % self._rollback_exception, referer: http://ec2-52-57-87-239.eu-central-1.compute.amazonaws.com/
[Sun Sep 25 10:28:54.756635 2016] [:error] [pid 1240:tid 140591149000448] [client 88.190.58.150:49929] InvalidRequestError: This Session's transaction has been rolled back due to a previous exception during flush. To begin a new transaction with this Session, first issue Session.rollback(). Original exception was: (DataError) invalid input syntax for integer: "ffffqsfqsfqs", referer: http://ec2-52-57-87-239.eu-central-1.compute.amazonaws.com/
[Sun Sep 25 10:28:54.756638 2016] [:error] [pid 1240:tid 140591149000448] [client 88.190.58.150:49929] LINE 1: ... '', '', '0000000', 'gaylord.marville@gmail.com', 'ffffqsfqs..., referer: http://ec2-52-57-87-239.eu-central-1.compute.amazonaws.com/
[Sun Sep 25 10:28:54.756640 2016] [:error] [pid 1240:tid 140591149000448] [client 88.190.58.150:49929]                                                              ^, referer: http://ec2-52-57-87-239.eu-central-1.compute.amazonaws.com/
[Sun Sep 25 10:28:54.756644 2016] [:error] [pid 1240:tid 140591149000448] [client 88.190.58.150:49929]  'INSERT INTO report (site_name, site_full_adress, site_adress_number, site_adress_street, site_adress_postcode, site_adress_city, site_administrative_area, site_adress_country, "site_ERPcategory", "site_ERPtype", client_lastname, client_firstname, client_full_adress, client_adress_number, client_adress_street, client_adress_postcode, client_adress_city, client_administrative_area, client_adress_country, client_phone, client_mail, report_number, "report_visitDate", "report_redactionDate", report_picture, "report_pictureOrientation", editor_lastname, editor_firstname, editor_full_adress, editor_adress_number, editor_adress_street, editor_adress_postcode, editor_adress_city, editor_administrative_area, editor_adress_country, editor_phone, editor_mail, frame_choice, user_id) VALUES (%(site_name)s, %(site_full_adress)s, %(site_adress_number)s, %(site_adress_street)s, %(site_adress_postcode)s, %(site_adress_city)s, %(site_administrative_area)s, %(site_adress_country)s, %(site_ERPcategory)s, %(site_ERPtype)s, %(client_lastname)s, %(client_firstname)s, %(client_full_adress)s, %(client_adress_number)s, %(client_adress_street)s, %(client_adress_postcode)s, %(client_adress_city)s, %(client_administrative_area)s, %(client_adress_country)s, %(client_phone)s, %(client_mail)s, %(report_number)s, %(report_visitDate)s, %(report_redactionDate)s, %(report_picture)s, %(report_pictureOrientation)s, %(editor_lastname)s, %(editor_firstname)s, %(editor_full_adress)s, %(editor_adress_number)s, %(editor_adress_street)s, %(editor_adress_postcode)s, %(editor_adress_city)s, %(editor_administrative_area)s, %(editor_adress_country)s, %(editor_phone)s, %(editor_mail)s, %(frame_choice)s, %(user_id)s) RETURNING report.id' {'site_name': u'fqsfqsf', 'report_number': u'ffffqsfqsfqs', 'editor_full_adress': u'sdfsdfsdf', 'editor_adress_street': u'', 'client_lastname': u'sdfsfddsf', 'site_ERPtype': u'D', 'editor_adress_city': u'', 'client_phone': u'0000000', 'editor_administrative_area': u'', 'client_firstname': u'dfsdfsdfsdf', 'user_id': 3, 'site_adress_postcode': u'', 'client_full_adress': u'fdsfsdfsds', 'report_visitDate': u'2016-09-22', 'report_redactionDate': u'2016-09-22', 'client_adress_city': u'', 'site_adress_number': u'', 'client_adress_country': u'', 'editor_adress_postcode': u'', 'client_adress_number': u'', 'client_mail': u'gaylord.marville@gmail.com', 'editor_phone': u'0000000', 'site_adress_city': u'', 'editor_adress_number': u'', 'editor_adress_country': u'', 'site_full_adress': u'qfdqsfsfsq', 'site_administrative_area': u'', 'report_pictureOrientation': 'None', 'editor_mail': u'gaylord.marville@gmail.com', 'report_picture': 'undefined.jpg', 'client_administrative_area': u'', 'client_adress_postcode': u'', 'site_ERPcategory': u'2', 'editor_lastname': u'sdfsdfsd', 'site_adress_street': u'', 'site_adress_country': u'', 'client_adress_street': u'', 'editor_firstname': u'fsdfsdfsdfds', 'frame_choice': 0}, referer: http://ec2-52-57-87-239.eu-central-1.compute.amazonaws.com/
[Sun Sep 25 10:28:57.672840 2016] [:error] [pid 1240:tid 140591283283712] [client 88.190.58.150:49926] mod_wsgi (pid=1240): Exception occurred processing WSGI script '/var/www/myapp.wsgi'., referer: http://ec2-52-57-87-239.eu-central-1.compute.amazonaws.com/
[Sun Sep 25 10:28:57.672876 2016] [:error] [pid 1240:tid 140591283283712] [client 88.190.58.150:49926] Traceback (most recent call last):, referer: http://ec2-52-57-87-239.eu-central-1.compute.amazonaws.com/
[Sun Sep 25 10:28:57.672890 2016] [:error] [pid 1240:tid 140591283283712] [client 88.190.58.150:49926]   File "/usr/lib/python2.7/dist-packages/flask/app.py", line 1836, in __call__, referer: http://ec2-52-57-87-239.eu-central-1.compute.amazonaws.com/
[Sun Sep 25 10:28:57.672909 2016] [:error] [pid 1240:tid 140591283283712] [client 88.190.58.150:49926]     return self.wsgi_app(environ, start_response), referer: http://ec2-52-57-87-239.eu-central-1.compute.amazonaws.com/
[Sun Sep 25 10:28:57.672915 2016] [:error] [pid 1240:tid 140591283283712] [client 88.190.58.150:49926]   File "/usr/lib/python2.7/dist-packages/flask/app.py", line 1820, in wsgi_app, referer: http://ec2-52-57-87-239.eu-central-1.compute.amazonaws.com/
[Sun Sep 25 10:28:57.672924 2016] [:error] [pid 1240:tid 140591283283712] [client 88.190.58.150:49926]     response = self.make_response(self.handle_exception(e)), referer: http://ec2-52-57-87-239.eu-central-1.compute.amazonaws.com/
[Sun Sep 25 10:28:57.672939 2016] [:error] [pid 1240:tid 140591283283712] [client 88.190.58.150:49926]   File "/usr/lib/python2.7/dist-packages/flask/app.py", line 1403, in handle_exception, referer: http://ec2-52-57-87-239.eu-central-1.compute.amazonaws.com/
[Sun Sep 25 10:28:57.672948 2016] [:error] [pid 1240:tid 140591283283712] [client 88.190.58.150:49926]     reraise(exc_type, exc_value, tb), referer: http://ec2-52-57-87-239.eu-central-1.compute.amazonaws.com/
[Sun Sep 25 10:28:57.672953 2016] [:error] [pid 1240:tid 140591283283712] [client 88.190.58.150:49926]   File "/usr/lib/python2.7/dist-packages/flask/app.py", line 1817, in wsgi_app, referer: http://ec2-52-57-87-239.eu-central-1.compute.amazonaws.com/
[Sun Sep 25 10:28:57.672960 2016] [:error] [pid 1240:tid 140591283283712] [client 88.190.58.150:49926]     response = self.full_dispatch_request(), referer: http://ec2-52-57-87-239.eu-central-1.compute.amazonaws.com/
[Sun Sep 25 10:28:57.672964 2016] [:error] [pid 1240:tid 140591283283712] [client 88.190.58.150:49926]   File "/usr/lib/python2.7/dist-packages/flask/app.py", line 1477, in full_dispatch_request, referer: http://ec2-52-57-87-239.eu-central-1.compute.amazonaws.com/
[Sun Sep 25 10:28:57.672971 2016] [:error] [pid 1240:tid 140591283283712] [client 88.190.58.150:49926]     rv = self.handle_user_exception(e), referer: http://ec2-52-57-87-239.eu-central-1.compute.amazonaws.com/
[Sun Sep 25 10:28:57.672975 2016] [:error] [pid 1240:tid 140591283283712] [client 88.190.58.150:49926]   File "/usr/lib/python2.7/dist-packages/flask/app.py", line 1381, in handle_user_exception, referer: http://ec2-52-57-87-239.eu-central-1.compute.amazonaws.com/
[Sun Sep 25 10:28:57.672982 2016] [:error] [pid 1240:tid 140591283283712] [client 88.190.58.150:49926]     reraise(exc_type, exc_value, tb), referer: http://ec2-52-57-87-239.eu-central-1.compute.amazonaws.com/
[Sun Sep 25 10:28:57.672986 2016] [:error] [pid 1240:tid 140591283283712] [client 88.190.58.150:49926]   File "/usr/lib/python2.7/dist-packages/flask/app.py", line 1475, in full_dispatch_request, referer: http://ec2-52-57-87-239.eu-central-1.compute.amazonaws.com/
[Sun Sep 25 10:28:57.672993 2016] [:error] [pid 1240:tid 140591283283712] [client 88.190.58.150:49926]     rv = self.dispatch_request(), referer: http://ec2-52-57-87-239.eu-central-1.compute.amazonaws.com/
[Sun Sep 25 10:28:57.672997 2016] [:error] [pid 1240:tid 140591283283712] [client 88.190.58.150:49926]   File "/usr/lib/python2.7/dist-packages/flask/app.py", line 1461, in dispatch_request, referer: http://ec2-52-57-87-239.eu-central-1.compute.amazonaws.com/
[Sun Sep 25 10:28:57.673004 2016] [:error] [pid 1240:tid 140591283283712] [client 88.190.58.150:49926]     return self.view_functions[rule.endpoint](**req.view_args), referer: http://ec2-52-57-87-239.eu-central-1.compute.amazonaws.com/
[Sun Sep 25 10:28:57.673008 2016] [:error] [pid 1240:tid 140591283283712] [client 88.190.58.150:49926]   File "/var/www/ItemCatalog/finalProject.py", line 69, in decorated_function, referer: http://ec2-52-57-87-239.eu-central-1.compute.amazonaws.com/
[Sun Sep 25 10:28:57.673015 2016] [:error] [pid 1240:tid 140591283283712] [client 88.190.58.150:49926]     return f(*args, **kwargs), referer: http://ec2-52-57-87-239.eu-central-1.compute.amazonaws.com/
[Sun Sep 25 10:28:57.673020 2016] [:error] [pid 1240:tid 140591283283712] [client 88.190.58.150:49926]   File "/var/www/ItemCatalog/finalProject.py", line 524, in newSingleReport, referer: http://ec2-52-57-87-239.eu-central-1.compute.amazonaws.com/
[Sun Sep 25 10:28:57.673027 2016] [:error] [pid 1240:tid 140591283283712] [client 88.190.58.150:49926]     user=login_session), referer: http://ec2-52-57-87-239.eu-central-1.compute.amazonaws.com/
[Sun Sep 25 10:28:57.673031 2016] [:error] [pid 1240:tid 140591283283712] [client 88.190.58.150:49926]   File "/usr/lib/python2.7/dist-packages/flask/templating.py", line 128, in render_template, referer: http://ec2-52-57-87-239.eu-central-1.compute.amazonaws.com/
[Sun Sep 25 10:28:57.673043 2016] [:error] [pid 1240:tid 140591283283712] [client 88.190.58.150:49926]     context, ctx.app), referer: http://ec2-52-57-87-239.eu-central-1.compute.amazonaws.com/
[Sun Sep 25 10:28:57.673048 2016] [:error] [pid 1240:tid 140591283283712] [client 88.190.58.150:49926]   File "/usr/lib/python2.7/dist-packages/flask/templating.py", line 110, in _render, referer: http://ec2-52-57-87-239.eu-central-1.compute.amazonaws.com/
[Sun Sep 25 10:28:57.673055 2016] [:error] [pid 1240:tid 140591283283712] [client 88.190.58.150:49926]     rv = template.render(context), referer: http://ec2-52-57-87-239.eu-central-1.compute.amazonaws.com/
[Sun Sep 25 10:28:57.673059 2016] [:error] [pid 1240:tid 140591283283712] [client 88.190.58.150:49926]   File "/usr/lib/python2.7/dist-packages/jinja2/environment.py", line 969, in render, referer: http://ec2-52-57-87-239.eu-central-1.compute.amazonaws.com/
[Sun Sep 25 10:28:57.673066 2016] [:error] [pid 1240:tid 140591283283712] [client 88.190.58.150:49926]     return self.environment.handle_exception(exc_info, True), referer: http://ec2-52-57-87-239.eu-central-1.compute.amazonaws.com/
[Sun Sep 25 10:28:57.673071 2016] [:error] [pid 1240:tid 140591283283712] [client 88.190.58.150:49926]   File "/usr/lib/python2.7/dist-packages/jinja2/environment.py", line 742, in handle_exception, referer: http://ec2-52-57-87-239.eu-central-1.compute.amazonaws.com/
[Sun Sep 25 10:28:57.673078 2016] [:error] [pid 1240:tid 140591283283712] [client 88.190.58.150:49926]     reraise(exc_type, exc_value, tb), referer: http://ec2-52-57-87-239.eu-central-1.compute.amazonaws.com/
[Sun Sep 25 10:28:57.673082 2016] [:error] [pid 1240:tid 140591283283712] [client 88.190.58.150:49926]   File "/var/www/ItemCatalog/templates/createsinglereport.html", line 86, in top-level template code, referer: http://ec2-52-57-87-239.eu-central-1.compute.amazonaws.com/
[Sun Sep 25 10:28:57.673089 2016] [:error] [pid 1240:tid 140591283283712] [client 88.190.58.150:49926]     {% for i in frames %}, referer: http://ec2-52-57-87-239.eu-central-1.compute.amazonaws.com/
[Sun Sep 25 10:28:57.673093 2016] [:error] [pid 1240:tid 140591283283712] [client 88.190.58.150:49926]   File "/usr/lib/python2.7/dist-packages/sqlalchemy/orm/query.py", line 2353, in __iter__, referer: http://ec2-52-57-87-239.eu-central-1.compute.amazonaws.com/
[Sun Sep 25 10:28:57.673101 2016] [:error] [pid 1240:tid 140591283283712] [client 88.190.58.150:49926]     return self._execute_and_instances(context), referer: http://ec2-52-57-87-239.eu-central-1.compute.amazonaws.com/
[Sun Sep 25 10:28:57.673105 2016] [:error] [pid 1240:tid 140591283283712] [client 88.190.58.150:49926]   File "/usr/lib/python2.7/dist-packages/sqlalchemy/orm/query.py", line 2366, in _execute_and_instances, referer: http://ec2-52-57-87-239.eu-central-1.compute.amazonaws.com/
[Sun Sep 25 10:28:57.673112 2016] [:error] [pid 1240:tid 140591283283712] [client 88.190.58.150:49926]     close_with_result=True), referer: http://ec2-52-57-87-239.eu-central-1.compute.amazonaws.com/
[Sun Sep 25 10:28:57.673116 2016] [:error] [pid 1240:tid 140591283283712] [client 88.190.58.150:49926]   File "/usr/lib/python2.7/dist-packages/sqlalchemy/orm/query.py", line 2357, in _connection_from_session, referer: http://ec2-52-57-87-239.eu-central-1.compute.amazonaws.com/
[Sun Sep 25 10:28:57.673123 2016] [:error] [pid 1240:tid 140591283283712] [client 88.190.58.150:49926]     **kw), referer: http://ec2-52-57-87-239.eu-central-1.compute.amazonaws.com/
[Sun Sep 25 10:28:57.673127 2016] [:error] [pid 1240:tid 140591283283712] [client 88.190.58.150:49926]   File "/usr/lib/python2.7/dist-packages/sqlalchemy/orm/session.py", line 799, in connection, referer: http://ec2-52-57-87-239.eu-central-1.compute.amazonaws.com/
[Sun Sep 25 10:28:57.673134 2016] [:error] [pid 1240:tid 140591283283712] [client 88.190.58.150:49926]     close_with_result=close_with_result), referer: http://ec2-52-57-87-239.eu-central-1.compute.amazonaws.com/
[Sun Sep 25 10:28:57.673143 2016] [:error] [pid 1240:tid 140591283283712] [client 88.190.58.150:49926]   File "/usr/lib/python2.7/dist-packages/sqlalchemy/orm/session.py", line 803, in _connection_for_bind, referer: http://ec2-52-57-87-239.eu-central-1.compute.amazonaws.com/
[Sun Sep 25 10:28:57.673156 2016] [:error] [pid 1240:tid 140591283283712] [client 88.190.58.150:49926]     return self.transaction._connection_for_bind(engine), referer: http://ec2-52-57-87-239.eu-central-1.compute.amazonaws.com/
[Sun Sep 25 10:28:57.673161 2016] [:error] [pid 1240:tid 140591283283712] [client 88.190.58.150:49926]   File "/usr/lib/python2.7/dist-packages/sqlalchemy/orm/session.py", line 282, in _connection_for_bind, referer: http://ec2-52-57-87-239.eu-central-1.compute.amazonaws.com/
[Sun Sep 25 10:28:57.673168 2016] [:error] [pid 1240:tid 140591283283712] [client 88.190.58.150:49926]     self._assert_active(), referer: http://ec2-52-57-87-239.eu-central-1.compute.amazonaws.com/
[Sun Sep 25 10:28:57.673173 2016] [:error] [pid 1240:tid 140591283283712] [client 88.190.58.150:49926]   File "/usr/lib/python2.7/dist-packages/sqlalchemy/orm/session.py", line 194, in _assert_active, referer: http://ec2-52-57-87-239.eu-central-1.compute.amazonaws.com/
[Sun Sep 25 10:28:57.673179 2016] [:error] [pid 1240:tid 140591283283712] [client 88.190.58.150:49926]     % self._rollback_exception, referer: http://ec2-52-57-87-239.eu-central-1.compute.amazonaws.com/
[Sun Sep 25 10:28:57.673193 2016] [:error] [pid 1240:tid 140591283283712] [client 88.190.58.150:49926] InvalidRequestError: This Session's transaction has been rolled back due to a previous exception during flush. To begin a new transaction with this Session, first issue Session.rollback(). Original exception was: (DataError) invalid input syntax for integer: "ffffqsfqsfqs", referer: http://ec2-52-57-87-239.eu-central-1.compute.amazonaws.com/
[Sun Sep 25 10:28:57.673196 2016] [:error] [pid 1240:tid 140591283283712] [client 88.190.58.150:49926] LINE 1: ... '', '', '0000000', 'gaylord.marville@gmail.com', 'ffffqsfqs..., referer: http://ec2-52-57-87-239.eu-central-1.compute.amazonaws.com/
[Sun Sep 25 10:28:57.673198 2016] [:error] [pid 1240:tid 140591283283712] [client 88.190.58.150:49926]                                                              ^, referer: http://ec2-52-57-87-239.eu-central-1.compute.amazonaws.com/
[Sun Sep 25 10:28:57.673202 2016] [:error] [pid 1240:tid 140591283283712] [client 88.190.58.150:49926]  'INSERT INTO report (site_name, site_full_adress, site_adress_number, site_adress_street, site_adress_postcode, site_adress_city, site_administrative_area, site_adress_country, "site_ERPcategory", "site_ERPtype", client_lastname, client_firstname, client_full_adress, client_adress_number, client_adress_street, client_adress_postcode, client_adress_city, client_administrative_area, client_adress_country, client_phone, client_mail, report_number, "report_visitDate", "report_redactionDate", report_picture, "report_pictureOrientation", editor_lastname, editor_firstname, editor_full_adress, editor_adress_number, editor_adress_street, editor_adress_postcode, editor_adress_city, editor_administrative_area, editor_adress_country, editor_phone, editor_mail, frame_choice, user_id) VALUES (%(site_name)s, %(site_full_adress)s, %(site_adress_number)s, %(site_adress_street)s, %(site_adress_postcode)s, %(site_adress_city)s, %(site_administrative_area)s, %(site_adress_country)s, %(site_ERPcategory)s, %(site_ERPtype)s, %(client_lastname)s, %(client_firstname)s, %(client_full_adress)s, %(client_adress_number)s, %(client_adress_street)s, %(client_adress_postcode)s, %(client_adress_city)s, %(client_administrative_area)s, %(client_adress_country)s, %(client_phone)s, %(client_mail)s, %(report_number)s, %(report_visitDate)s, %(report_redactionDate)s, %(report_picture)s, %(report_pictureOrientation)s, %(editor_lastname)s, %(editor_firstname)s, %(editor_full_adress)s, %(editor_adress_number)s, %(editor_adress_street)s, %(editor_adress_postcode)s, %(editor_adress_city)s, %(editor_administrative_area)s, %(editor_adress_country)s, %(editor_phone)s, %(editor_mail)s, %(frame_choice)s, %(user_id)s) RETURNING report.id' {'site_name': u'fqsfqsf', 'report_number': u'ffffqsfqsfqs', 'editor_full_adress': u'sdfsdfsdf', 'editor_adress_street': u'', 'client_lastname': u'sdfsfddsf', 'site_ERPtype': u'D', 'editor_adress_city': u'', 'client_phone': u'0000000', 'editor_administrative_area': u'', 'client_firstname': u'dfsdfsdfsdf', 'user_id': 3, 'site_adress_postcode': u'', 'client_full_adress': u'fdsfsdfsds', 'report_visitDate': u'2016-09-22', 'report_redactionDate': u'2016-09-22', 'client_adress_city': u'', 'site_adress_number': u'', 'client_adress_country': u'', 'editor_adress_postcode': u'', 'client_adress_number': u'', 'client_mail': u'gaylord.marville@gmail.com', 'editor_phone': u'0000000', 'site_adress_city': u'', 'editor_adress_number': u'', 'editor_adress_country': u'', 'site_full_adress': u'qfdqsfsfsq', 'site_administrative_area': u'', 'report_pictureOrientation': 'None', 'editor_mail': u'gaylord.marville@gmail.com', 'report_picture': 'undefined.jpg', 'client_administrative_area': u'', 'client_adress_postcode': u'', 'site_ERPcategory': u'2', 'editor_lastname': u'sdfsdfsd', 'site_adress_street': u'', 'site_adress_country': u'', 'client_adress_street': u'', 'editor_firstname': u'fsdfsdfsdfds', 'frame_choice': 0}, referer: http://ec2-52-57-87-239.eu-central-1.compute.amazonaws.com/
[Sun Sep 25 10:29:04.309283 2016] [:error] [pid 1240:tid 140591316854528] [client 88.190.58.150:49938] mod_wsgi (pid=1240): Exception occurred processing WSGI script '/var/www/myapp.wsgi'.
[Sun Sep 25 10:29:04.309321 2016] [:error] [pid 1240:tid 140591316854528] [client 88.190.58.150:49938] Traceback (most recent call last):
[Sun Sep 25 10:29:04.309336 2016] [:error] [pid 1240:tid 140591316854528] [client 88.190.58.150:49938]   File "/usr/lib/python2.7/dist-packages/flask/app.py", line 1836, in __call__
[Sun Sep 25 10:29:04.309356 2016] [:error] [pid 1240:tid 140591316854528] [client 88.190.58.150:49938]     return self.wsgi_app(environ, start_response)
[Sun Sep 25 10:29:04.309363 2016] [:error] [pid 1240:tid 140591316854528] [client 88.190.58.150:49938]   File "/usr/lib/python2.7/dist-packages/flask/app.py", line 1820, in wsgi_app
[Sun Sep 25 10:29:04.309372 2016] [:error] [pid 1240:tid 140591316854528] [client 88.190.58.150:49938]     response = self.make_response(self.handle_exception(e))
[Sun Sep 25 10:29:04.309378 2016] [:error] [pid 1240:tid 140591316854528] [client 88.190.58.150:49938]   File "/usr/lib/python2.7/dist-packages/flask/app.py", line 1403, in handle_exception
[Sun Sep 25 10:29:04.309385 2016] [:error] [pid 1240:tid 140591316854528] [client 88.190.58.150:49938]     reraise(exc_type, exc_value, tb)
[Sun Sep 25 10:29:04.309391 2016] [:error] [pid 1240:tid 140591316854528] [client 88.190.58.150:49938]   File "/usr/lib/python2.7/dist-packages/flask/app.py", line 1817, in wsgi_app
[Sun Sep 25 10:29:04.309398 2016] [:error] [pid 1240:tid 140591316854528] [client 88.190.58.150:49938]     response = self.full_dispatch_request()
[Sun Sep 25 10:29:04.309402 2016] [:error] [pid 1240:tid 140591316854528] [client 88.190.58.150:49938]   File "/usr/lib/python2.7/dist-packages/flask/app.py", line 1477, in full_dispatch_request
[Sun Sep 25 10:29:04.309409 2016] [:error] [pid 1240:tid 140591316854528] [client 88.190.58.150:49938]     rv = self.handle_user_exception(e)
[Sun Sep 25 10:29:04.309414 2016] [:error] [pid 1240:tid 140591316854528] [client 88.190.58.150:49938]   File "/usr/lib/python2.7/dist-packages/flask/app.py", line 1381, in handle_user_exception
[Sun Sep 25 10:29:04.309421 2016] [:error] [pid 1240:tid 140591316854528] [client 88.190.58.150:49938]     reraise(exc_type, exc_value, tb)
[Sun Sep 25 10:29:04.309426 2016] [:error] [pid 1240:tid 140591316854528] [client 88.190.58.150:49938]   File "/usr/lib/python2.7/dist-packages/flask/app.py", line 1475, in full_dispatch_request
[Sun Sep 25 10:29:04.309445 2016] [:error] [pid 1240:tid 140591316854528] [client 88.190.58.150:49938]     rv = self.dispatch_request()
[Sun Sep 25 10:29:04.309450 2016] [:error] [pid 1240:tid 140591316854528] [client 88.190.58.150:49938]   File "/usr/lib/python2.7/dist-packages/flask/app.py", line 1461, in dispatch_request
[Sun Sep 25 10:29:04.309467 2016] [:error] [pid 1240:tid 140591316854528] [client 88.190.58.150:49938]     return self.view_functions[rule.endpoint](**req.view_args)
[Sun Sep 25 10:29:04.309473 2016] [:error] [pid 1240:tid 140591316854528] [client 88.190.58.150:49938]   File "/var/www/ItemCatalog/finalProject.py", line 405, in showAllReports
[Sun Sep 25 10:29:04.309482 2016] [:error] [pid 1240:tid 140591316854528] [client 88.190.58.150:49938]     customised=reports)
[Sun Sep 25 10:29:04.309487 2016] [:error] [pid 1240:tid 140591316854528] [client 88.190.58.150:49938]   File "/usr/lib/python2.7/dist-packages/flask/templating.py", line 128, in render_template
[Sun Sep 25 10:29:04.309495 2016] [:error] [pid 1240:tid 140591316854528] [client 88.190.58.150:49938]     context, ctx.app)
[Sun Sep 25 10:29:04.309500 2016] [:error] [pid 1240:tid 140591316854528] [client 88.190.58.150:49938]   File "/usr/lib/python2.7/dist-packages/flask/templating.py", line 110, in _render
[Sun Sep 25 10:29:04.309507 2016] [:error] [pid 1240:tid 140591316854528] [client 88.190.58.150:49938]     rv = template.render(context)
[Sun Sep 25 10:29:04.309512 2016] [:error] [pid 1240:tid 140591316854528] [client 88.190.58.150:49938]   File "/usr/lib/python2.7/dist-packages/jinja2/environment.py", line 969, in render
[Sun Sep 25 10:29:04.309520 2016] [:error] [pid 1240:tid 140591316854528] [client 88.190.58.150:49938]     return self.environment.handle_exception(exc_info, True)
[Sun Sep 25 10:29:04.309524 2016] [:error] [pid 1240:tid 140591316854528] [client 88.190.58.150:49938]   File "/usr/lib/python2.7/dist-packages/jinja2/environment.py", line 742, in handle_exception
[Sun Sep 25 10:29:04.309532 2016] [:error] [pid 1240:tid 140591316854528] [client 88.190.58.150:49938]     reraise(exc_type, exc_value, tb)
[Sun Sep 25 10:29:04.309536 2016] [:error] [pid 1240:tid 140591316854528] [client 88.190.58.150:49938]   File "/var/www/ItemCatalog/templates/reports.html", line 97, in top-level template code
[Sun Sep 25 10:29:04.309651 2016] [:error] [pid 1240:tid 140591316854528] [client 88.190.58.150:49938]     {% for i in reports %}
[Sun Sep 25 10:29:04.309660 2016] [:error] [pid 1240:tid 140591316854528] [client 88.190.58.150:49938]   File "/usr/lib/python2.7/dist-packages/sqlalchemy/orm/query.py", line 2353, in __iter__
[Sun Sep 25 10:29:04.309672 2016] [:error] [pid 1240:tid 140591316854528] [client 88.190.58.150:49938]     return self._execute_and_instances(context)
[Sun Sep 25 10:29:04.309677 2016] [:error] [pid 1240:tid 140591316854528] [client 88.190.58.150:49938]   File "/usr/lib/python2.7/dist-packages/sqlalchemy/orm/query.py", line 2366, in _execute_and_instances
[Sun Sep 25 10:29:04.309685 2016] [:error] [pid 1240:tid 140591316854528] [client 88.190.58.150:49938]     close_with_result=True)
[Sun Sep 25 10:29:04.309690 2016] [:error] [pid 1240:tid 140591316854528] [client 88.190.58.150:49938]   File "/usr/lib/python2.7/dist-packages/sqlalchemy/orm/query.py", line 2357, in _connection_from_session
[Sun Sep 25 10:29:04.309697 2016] [:error] [pid 1240:tid 140591316854528] [client 88.190.58.150:49938]     **kw)
[Sun Sep 25 10:29:04.309702 2016] [:error] [pid 1240:tid 140591316854528] [client 88.190.58.150:49938]   File "/usr/lib/python2.7/dist-packages/sqlalchemy/orm/session.py", line 799, in connection
[Sun Sep 25 10:29:04.309710 2016] [:error] [pid 1240:tid 140591316854528] [client 88.190.58.150:49938]     close_with_result=close_with_result)
[Sun Sep 25 10:29:04.309715 2016] [:error] [pid 1240:tid 140591316854528] [client 88.190.58.150:49938]   File "/usr/lib/python2.7/dist-packages/sqlalchemy/orm/session.py", line 803, in _connection_for_bind
[Sun Sep 25 10:29:04.309722 2016] [:error] [pid 1240:tid 140591316854528] [client 88.190.58.150:49938]     return self.transaction._connection_for_bind(engine)
[Sun Sep 25 10:29:04.309726 2016] [:error] [pid 1240:tid 140591316854528] [client 88.190.58.150:49938]   File "/usr/lib/python2.7/dist-packages/sqlalchemy/orm/session.py", line 282, in _connection_for_bind
[Sun Sep 25 10:29:04.309741 2016] [:error] [pid 1240:tid 140591316854528] [client 88.190.58.150:49938]     self._assert_active()
[Sun Sep 25 10:29:04.309747 2016] [:error] [pid 1240:tid 140591316854528] [client 88.190.58.150:49938]   File "/usr/lib/python2.7/dist-packages/sqlalchemy/orm/session.py", line 194, in _assert_active
[Sun Sep 25 10:29:04.309754 2016] [:error] [pid 1240:tid 140591316854528] [client 88.190.58.150:49938]     % self._rollback_exception
[Sun Sep 25 10:29:04.309769 2016] [:error] [pid 1240:tid 140591316854528] [client 88.190.58.150:49938] InvalidRequestError: This Session's transaction has been rolled back due to a previous exception during flush. To begin a new transaction with this Session, first issue Session.rollback(). Original exception was: (DataError) invalid input syntax for integer: "ffffqsfqsfqs"
[Sun Sep 25 10:29:04.309772 2016] [:error] [pid 1240:tid 140591316854528] [client 88.190.58.150:49938] LINE 1: ... '', '', '0000000', 'gaylord.marville@gmail.com', 'ffffqsfqs...
[Sun Sep 25 10:29:04.309774 2016] [:error] [pid 1240:tid 140591316854528] [client 88.190.58.150:49938]                                                              ^
[Sun Sep 25 10:29:04.309778 2016] [:error] [pid 1240:tid 140591316854528] [client 88.190.58.150:49938]  'INSERT INTO report (site_name, site_full_adress, site_adress_number, site_adress_street, site_adress_postcode, site_adress_city, site_administrative_area, site_adress_country, "site_ERPcategory", "site_ERPtype", client_lastname, client_firstname, client_full_adress, client_adress_number, client_adress_street, client_adress_postcode, client_adress_city, client_administrative_area, client_adress_country, client_phone, client_mail, report_number, "report_visitDate", "report_redactionDate", report_picture, "report_pictureOrientation", editor_lastname, editor_firstname, editor_full_adress, editor_adress_number, editor_adress_street, editor_adress_postcode, editor_adress_city, editor_administrative_area, editor_adress_country, editor_phone, editor_mail, frame_choice, user_id) VALUES (%(site_name)s, %(site_full_adress)s, %(site_adress_number)s, %(site_adress_street)s, %(site_adress_postcode)s, %(site_adress_city)s, %(site_administrative_area)s, %(site_adress_country)s, %(site_ERPcategory)s, %(site_ERPtype)s, %(client_lastname)s, %(client_firstname)s, %(client_full_adress)s, %(client_adress_number)s, %(client_adress_street)s, %(client_adress_postcode)s, %(client_adress_city)s, %(client_administrative_area)s, %(client_adress_country)s, %(client_phone)s, %(client_mail)s, %(report_number)s, %(report_visitDate)s, %(report_redactionDate)s, %(report_picture)s, %(report_pictureOrientation)s, %(editor_lastname)s, %(editor_firstname)s, %(editor_full_adress)s, %(editor_adress_number)s, %(editor_adress_street)s, %(editor_adress_postcode)s, %(editor_adress_city)s, %(editor_administrative_area)s, %(editor_adress_country)s, %(editor_phone)s, %(editor_mail)s, %(frame_choice)s, %(user_id)s) RETURNING report.id' {'site_name': u'fqsfqsf', 'report_number': u'ffffqsfqsfqs', 'editor_full_adress': u'sdfsdfsdf', 'editor_adress_street': u'', 'client_lastname': u'sdfsfddsf', 'site_ERPtype': u'D', 'editor_adress_city': u'', 'client_phone': u'0000000', 'editor_administrative_area': u'', 'client_firstname': u'dfsdfsdfsdf', 'user_id': 3, 'site_adress_postcode': u'', 'client_full_adress': u'fdsfsdfsds', 'report_visitDate': u'2016-09-22', 'report_redactionDate': u'2016-09-22', 'client_adress_city': u'', 'site_adress_number': u'', 'client_adress_country': u'', 'editor_adress_postcode': u'', 'client_adress_number': u'', 'client_mail': u'gaylord.marville@gmail.com', 'editor_phone': u'0000000', 'site_adress_city': u'', 'editor_adress_number': u'', 'editor_adress_country': u'', 'site_full_adress': u'qfdqsfsfsq', 'site_administrative_area': u'', 'report_pictureOrientation': 'None', 'editor_mail': u'gaylord.marville@gmail.com', 'report_picture': 'undefined.jpg', 'client_administrative_area': u'', 'client_adress_postcode': u'', 'site_ERPcategory': u'2', 'editor_lastname': u'sdfsdfsd', 'site_adress_street': u'', 'site_adress_country': u'', 'client_adress_street': u'', 'editor_firstname': u'fsdfsdfsdfds', 'frame_choice': 0}
[Sun Sep 25 10:30:23.696756 2016] [mpm_event:notice] [pid 1237:tid 140591514777472] AH00491: caught SIGTERM, shutting down
[Sun Sep 25 10:30:24.683240 2016] [mpm_event:notice] [pid 1789:tid 140668225419136] AH00489: Apache/2.4.7 (Ubuntu) mod_wsgi/3.4 Python/2.7.6 configured -- resuming normal operations
[Sun Sep 25 10:30:24.683315 2016] [core:notice] [pid 1789:tid 140668225419136] AH00094: Command line: '/usr/sbin/apache2'
[Sun Sep 25 10:30:30.460485 2016] [:info] [pid 1793:tid 140668013893376] [client 88.190.58.150:49963] mod_wsgi (pid=1793, process='', application='ec2-52-57-15-38.eu-central-1.compute.amazonaws.com|'): Loading WSGI script '/var/www/myapp.wsgi'.
[Sun Sep 25 10:30:30.784936 2016] [:info] [pid 1792:tid 140667946751744] [client 88.190.58.150:49971] mod_wsgi (pid=1792, process='', application='ec2-52-57-15-38.eu-central-1.compute.amazonaws.com|'): Loading WSGI script '/var/www/myapp.wsgi'., referer: http://ec2-52-57-87-239.eu-central-1.compute.amazonaws.com/
[Sun Sep 25 10:30:48.555919 2016] [:error] [pid 1792:tid 140667971929856] [client 88.190.58.150:49971] mod_wsgi (pid=1792): Exception occurred processing WSGI script '/var/www/myapp.wsgi'., referer: http://ec2-52-57-87-239.eu-central-1.compute.amazonaws.com/reports/new?
[Sun Sep 25 10:30:48.555957 2016] [:error] [pid 1792:tid 140667971929856] [client 88.190.58.150:49971] Traceback (most recent call last):, referer: http://ec2-52-57-87-239.eu-central-1.compute.amazonaws.com/reports/new?
[Sun Sep 25 10:30:48.555976 2016] [:error] [pid 1792:tid 140667971929856] [client 88.190.58.150:49971]   File "/usr/lib/python2.7/dist-packages/flask/app.py", line 1836, in __call__, referer: http://ec2-52-57-87-239.eu-central-1.compute.amazonaws.com/reports/new?
[Sun Sep 25 10:30:48.556350 2016] [:error] [pid 1792:tid 140667971929856] [client 88.190.58.150:49971]     return self.wsgi_app(environ, start_response), referer: http://ec2-52-57-87-239.eu-central-1.compute.amazonaws.com/reports/new?
[Sun Sep 25 10:30:48.556364 2016] [:error] [pid 1792:tid 140667971929856] [client 88.190.58.150:49971]   File "/usr/lib/python2.7/dist-packages/flask/app.py", line 1820, in wsgi_app, referer: http://ec2-52-57-87-239.eu-central-1.compute.amazonaws.com/reports/new?
[Sun Sep 25 10:30:48.556377 2016] [:error] [pid 1792:tid 140667971929856] [client 88.190.58.150:49971]     response = self.make_response(self.handle_exception(e)), referer: http://ec2-52-57-87-239.eu-central-1.compute.amazonaws.com/reports/new?
[Sun Sep 25 10:30:48.556383 2016] [:error] [pid 1792:tid 140667971929856] [client 88.190.58.150:49971]   File "/usr/lib/python2.7/dist-packages/flask/app.py", line 1403, in handle_exception, referer: http://ec2-52-57-87-239.eu-central-1.compute.amazonaws.com/reports/new?
[Sun Sep 25 10:30:48.556391 2016] [:error] [pid 1792:tid 140667971929856] [client 88.190.58.150:49971]     reraise(exc_type, exc_value, tb), referer: http://ec2-52-57-87-239.eu-central-1.compute.amazonaws.com/reports/new?
[Sun Sep 25 10:30:48.556396 2016] [:error] [pid 1792:tid 140667971929856] [client 88.190.58.150:49971]   File "/usr/lib/python2.7/dist-packages/flask/app.py", line 1817, in wsgi_app, referer: http://ec2-52-57-87-239.eu-central-1.compute.amazonaws.com/reports/new?
[Sun Sep 25 10:30:48.556403 2016] [:error] [pid 1792:tid 140667971929856] [client 88.190.58.150:49971]     response = self.full_dispatch_request(), referer: http://ec2-52-57-87-239.eu-central-1.compute.amazonaws.com/reports/new?
[Sun Sep 25 10:30:48.556408 2016] [:error] [pid 1792:tid 140667971929856] [client 88.190.58.150:49971]   File "/usr/lib/python2.7/dist-packages/flask/app.py", line 1477, in full_dispatch_request, referer: http://ec2-52-57-87-239.eu-central-1.compute.amazonaws.com/reports/new?
[Sun Sep 25 10:30:48.556415 2016] [:error] [pid 1792:tid 140667971929856] [client 88.190.58.150:49971]     rv = self.handle_user_exception(e), referer: http://ec2-52-57-87-239.eu-central-1.compute.amazonaws.com/reports/new?
[Sun Sep 25 10:30:48.556430 2016] [:error] [pid 1792:tid 140667971929856] [client 88.190.58.150:49971]   File "/usr/lib/python2.7/dist-packages/flask/app.py", line 1381, in handle_user_exception, referer: http://ec2-52-57-87-239.eu-central-1.compute.amazonaws.com/reports/new?
[Sun Sep 25 10:30:48.556437 2016] [:error] [pid 1792:tid 140667971929856] [client 88.190.58.150:49971]     reraise(exc_type, exc_value, tb), referer: http://ec2-52-57-87-239.eu-central-1.compute.amazonaws.com/reports/new?
[Sun Sep 25 10:30:48.556442 2016] [:error] [pid 1792:tid 140667971929856] [client 88.190.58.150:49971]   File "/usr/lib/python2.7/dist-packages/flask/app.py", line 1475, in full_dispatch_request, referer: http://ec2-52-57-87-239.eu-central-1.compute.amazonaws.com/reports/new?
[Sun Sep 25 10:30:48.556448 2016] [:error] [pid 1792:tid 140667971929856] [client 88.190.58.150:49971]     rv = self.dispatch_request(), referer: http://ec2-52-57-87-239.eu-central-1.compute.amazonaws.com/reports/new?
[Sun Sep 25 10:30:48.556452 2016] [:error] [pid 1792:tid 140667971929856] [client 88.190.58.150:49971]   File "/usr/lib/python2.7/dist-packages/flask/app.py", line 1461, in dispatch_request, referer: http://ec2-52-57-87-239.eu-central-1.compute.amazonaws.com/reports/new?
[Sun Sep 25 10:30:48.556459 2016] [:error] [pid 1792:tid 140667971929856] [client 88.190.58.150:49971]     return self.view_functions[rule.endpoint](**req.view_args), referer: http://ec2-52-57-87-239.eu-central-1.compute.amazonaws.com/reports/new?
[Sun Sep 25 10:30:48.556463 2016] [:error] [pid 1792:tid 140667971929856] [client 88.190.58.150:49971]   File "/var/www/ItemCatalog/finalProject.py", line 69, in decorated_function, referer: http://ec2-52-57-87-239.eu-central-1.compute.amazonaws.com/reports/new?
[Sun Sep 25 10:30:48.556616 2016] [:error] [pid 1792:tid 140667971929856] [client 88.190.58.150:49971]     return f(*args, **kwargs), referer: http://ec2-52-57-87-239.eu-central-1.compute.amazonaws.com/reports/new?
[Sun Sep 25 10:30:48.556627 2016] [:error] [pid 1792:tid 140667971929856] [client 88.190.58.150:49971]   File "/var/www/ItemCatalog/finalProject.py", line 503, in newSingleReport, referer: http://ec2-52-57-87-239.eu-central-1.compute.amazonaws.com/reports/new?
[Sun Sep 25 10:30:48.556637 2016] [:error] [pid 1792:tid 140667971929856] [client 88.190.58.150:49971]     session.commit(), referer: http://ec2-52-57-87-239.eu-central-1.compute.amazonaws.com/reports/new?
[Sun Sep 25 10:30:48.556642 2016] [:error] [pid 1792:tid 140667971929856] [client 88.190.58.150:49971]   File "/usr/lib/python2.7/dist-packages/sqlalchemy/orm/session.py", line 721, in commit, referer: http://ec2-52-57-87-239.eu-central-1.compute.amazonaws.com/reports/new?
[Sun Sep 25 10:30:48.557026 2016] [:error] [pid 1792:tid 140667971929856] [client 88.190.58.150:49971]     self.transaction.commit(), referer: http://ec2-52-57-87-239.eu-central-1.compute.amazonaws.com/reports/new?
[Sun Sep 25 10:30:48.557037 2016] [:error] [pid 1792:tid 140667971929856] [client 88.190.58.150:49971]   File "/usr/lib/python2.7/dist-packages/sqlalchemy/orm/session.py", line 354, in commit, referer: http://ec2-52-57-87-239.eu-central-1.compute.amazonaws.com/reports/new?
[Sun Sep 25 10:30:48.557048 2016] [:error] [pid 1792:tid 140667971929856] [client 88.190.58.150:49971]     self._prepare_impl(), referer: http://ec2-52-57-87-239.eu-central-1.compute.amazonaws.com/reports/new?
[Sun Sep 25 10:30:48.557053 2016] [:error] [pid 1792:tid 140667971929856] [client 88.190.58.150:49971]   File "/usr/lib/python2.7/dist-packages/sqlalchemy/orm/session.py", line 334, in _prepare_impl, referer: http://ec2-52-57-87-239.eu-central-1.compute.amazonaws.com/reports/new?
[Sun Sep 25 10:30:48.557060 2016] [:error] [pid 1792:tid 140667971929856] [client 88.190.58.150:49971]     self.session.flush(), referer: http://ec2-52-57-87-239.eu-central-1.compute.amazonaws.com/reports/new?
[Sun Sep 25 10:30:48.557065 2016] [:error] [pid 1792:tid 140667971929856] [client 88.190.58.150:49971]   File "/usr/lib/python2.7/dist-packages/sqlalchemy/orm/session.py", line 1818, in flush, referer: http://ec2-52-57-87-239.eu-central-1.compute.amazonaws.com/reports/new?
[Sun Sep 25 10:30:48.557077 2016] [:error] [pid 1792:tid 140667971929856] [client 88.190.58.150:49971]     self._flush(objects), referer: http://ec2-52-57-87-239.eu-central-1.compute.amazonaws.com/reports/new?
[Sun Sep 25 10:30:48.557083 2016] [:error] [pid 1792:tid 140667971929856] [client 88.190.58.150:49971]   File "/usr/lib/python2.7/dist-packages/sqlalchemy/orm/session.py", line 1936, in _flush, referer: http://ec2-52-57-87-239.eu-central-1.compute.amazonaws.com/reports/new?
[Sun Sep 25 10:30:48.557090 2016] [:error] [pid 1792:tid 140667971929856] [client 88.190.58.150:49971]     transaction.rollback(_capture_exception=True), referer: http://ec2-52-57-87-239.eu-central-1.compute.amazonaws.com/reports/new?
[Sun Sep 25 10:30:48.557095 2016] [:error] [pid 1792:tid 140667971929856] [client 88.190.58.150:49971]   File "/usr/lib/python2.7/dist-packages/sqlalchemy/util/langhelpers.py", line 58, in __exit__, referer: http://ec2-52-57-87-239.eu-central-1.compute.amazonaws.com/reports/new?
[Sun Sep 25 10:30:48.557292 2016] [:error] [pid 1792:tid 140667971929856] [client 88.190.58.150:49971]     compat.reraise(exc_type, exc_value, exc_tb), referer: http://ec2-52-57-87-239.eu-central-1.compute.amazonaws.com/reports/new?
[Sun Sep 25 10:30:48.557314 2016] [:error] [pid 1792:tid 140667971929856] [client 88.190.58.150:49971]   File "/usr/lib/python2.7/dist-packages/sqlalchemy/orm/session.py", line 1900, in _flush, referer: http://ec2-52-57-87-239.eu-central-1.compute.amazonaws.com/reports/new?
[Sun Sep 25 10:30:48.557327 2016] [:error] [pid 1792:tid 140667971929856] [client 88.190.58.150:49971]     flush_context.execute(), referer: http://ec2-52-57-87-239.eu-central-1.compute.amazonaws.com/reports/new?
[Sun Sep 25 10:30:48.557333 2016] [:error] [pid 1792:tid 140667971929856] [client 88.190.58.150:49971]   File "/usr/lib/python2.7/dist-packages/sqlalchemy/orm/unitofwork.py", line 372, in execute, referer: http://ec2-52-57-87-239.eu-central-1.compute.amazonaws.com/reports/new?
[Sun Sep 25 10:30:48.557466 2016] [:error] [pid 1792:tid 140667971929856] [client 88.190.58.150:49971]     rec.execute(self), referer: http://ec2-52-57-87-239.eu-central-1.compute.amazonaws.com/reports/new?
[Sun Sep 25 10:30:48.557476 2016] [:error] [pid 1792:tid 140667971929856] [client 88.190.58.150:49971]   File "/usr/lib/python2.7/dist-packages/sqlalchemy/orm/unitofwork.py", line 525, in execute, referer: http://ec2-52-57-87-239.eu-central-1.compute.amazonaws.com/reports/new?
[Sun Sep 25 10:30:48.557486 2016] [:error] [pid 1792:tid 140667971929856] [client 88.190.58.150:49971]     uow, referer: http://ec2-52-57-87-239.eu-central-1.compute.amazonaws.com/reports/new?
[Sun Sep 25 10:30:48.557492 2016] [:error] [pid 1792:tid 140667971929856] [client 88.190.58.150:49971]   File "/usr/lib/python2.7/dist-packages/sqlalchemy/orm/persistence.py", line 64, in save_obj, referer: http://ec2-52-57-87-239.eu-central-1.compute.amazonaws.com/reports/new?
[Sun Sep 25 10:30:48.557685 2016] [:error] [pid 1792:tid 140667971929856] [client 88.190.58.150:49971]     table, insert), referer: http://ec2-52-57-87-239.eu-central-1.compute.amazonaws.com/reports/new?
[Sun Sep 25 10:30:48.557696 2016] [:error] [pid 1792:tid 140667971929856] [client 88.190.58.150:49971]   File "/usr/lib/python2.7/dist-packages/sqlalchemy/orm/persistence.py", line 569, in _emit_insert_statements, referer: http://ec2-52-57-87-239.eu-central-1.compute.amazonaws.com/reports/new?
[Sun Sep 25 10:30:48.557707 2016] [:error] [pid 1792:tid 140667971929856] [client 88.190.58.150:49971]     execute(statement, params), referer: http://ec2-52-57-87-239.eu-central-1.compute.amazonaws.com/reports/new?
[Sun Sep 25 10:30:48.557712 2016] [:error] [pid 1792:tid 140667971929856] [client 88.190.58.150:49971]   File "/usr/lib/python2.7/dist-packages/sqlalchemy/engine/base.py", line 662, in execute, referer: http://ec2-52-57-87-239.eu-central-1.compute.amazonaws.com/reports/new?
[Sun Sep 25 10:30:48.558014 2016] [:error] [pid 1792:tid 140667971929856] [client 88.190.58.150:49971]     params), referer: http://ec2-52-57-87-239.eu-central-1.compute.amazonaws.com/reports/new?
[Sun Sep 25 10:30:48.558037 2016] [:error] [pid 1792:tid 140667971929856] [client 88.190.58.150:49971]   File "/usr/lib/python2.7/dist-packages/sqlalchemy/engine/base.py", line 761, in _execute_clauseelement, referer: http://ec2-52-57-87-239.eu-central-1.compute.amazonaws.com/reports/new?
[Sun Sep 25 10:30:48.558048 2016] [:error] [pid 1792:tid 140667971929856] [client 88.190.58.150:49971]     compiled_sql, distilled_params, referer: http://ec2-52-57-87-239.eu-central-1.compute.amazonaws.com/reports/new?
[Sun Sep 25 10:30:48.558053 2016] [:error] [pid 1792:tid 140667971929856] [client 88.190.58.150:49971]   File "/usr/lib/python2.7/dist-packages/sqlalchemy/engine/base.py", line 874, in _execute_context, referer: http://ec2-52-57-87-239.eu-central-1.compute.amazonaws.com/reports/new?
[Sun Sep 25 10:30:48.558061 2016] [:error] [pid 1792:tid 140667971929856] [client 88.190.58.150:49971]     context), referer: http://ec2-52-57-87-239.eu-central-1.compute.amazonaws.com/reports/new?
[Sun Sep 25 10:30:48.558065 2016] [:error] [pid 1792:tid 140667971929856] [client 88.190.58.150:49971]   File "/usr/lib/python2.7/dist-packages/sqlalchemy/engine/base.py", line 1024, in _handle_dbapi_exception, referer: http://ec2-52-57-87-239.eu-central-1.compute.amazonaws.com/reports/new?
[Sun Sep 25 10:30:48.558072 2016] [:error] [pid 1792:tid 140667971929856] [client 88.190.58.150:49971]     exc_info, referer: http://ec2-52-57-87-239.eu-central-1.compute.amazonaws.com/reports/new?
[Sun Sep 25 10:30:48.558077 2016] [:error] [pid 1792:tid 140667971929856] [client 88.190.58.150:49971]   File "/usr/lib/python2.7/dist-packages/sqlalchemy/util/compat.py", line 196, in raise_from_cause, referer: http://ec2-52-57-87-239.eu-central-1.compute.amazonaws.com/reports/new?
[Sun Sep 25 10:30:48.558125 2016] [:error] [pid 1792:tid 140667971929856] [client 88.190.58.150:49971]     reraise(type(exception), exception, tb=exc_tb), referer: http://ec2-52-57-87-239.eu-central-1.compute.amazonaws.com/reports/new?
[Sun Sep 25 10:30:48.558132 2016] [:error] [pid 1792:tid 140667971929856] [client 88.190.58.150:49971]   File "/usr/lib/python2.7/dist-packages/sqlalchemy/engine/base.py", line 867, in _execute_context, referer: http://ec2-52-57-87-239.eu-central-1.compute.amazonaws.com/reports/new?
[Sun Sep 25 10:30:48.558143 2016] [:error] [pid 1792:tid 140667971929856] [client 88.190.58.150:49971]     context), referer: http://ec2-52-57-87-239.eu-central-1.compute.amazonaws.com/reports/new?
[Sun Sep 25 10:30:48.558148 2016] [:error] [pid 1792:tid 140667971929856] [client 88.190.58.150:49971]   File "/usr/lib/python2.7/dist-packages/sqlalchemy/engine/default.py", line 324, in do_execute, referer: http://ec2-52-57-87-239.eu-central-1.compute.amazonaws.com/reports/new?
[Sun Sep 25 10:30:48.558300 2016] [:error] [pid 1792:tid 140667971929856] [client 88.190.58.150:49971]     cursor.execute(statement, parameters), referer: http://ec2-52-57-87-239.eu-central-1.compute.amazonaws.com/reports/new?
[Sun Sep 25 10:30:48.558377 2016] [:error] [pid 1792:tid 140667971929856] [client 88.190.58.150:49971] DataError: (DataError) invalid input syntax for integer: "", referer: http://ec2-52-57-87-239.eu-central-1.compute.amazonaws.com/reports/new?
[Sun Sep 25 10:30:48.558381 2016] [:error] [pid 1792:tid 140667971929856] [client 88.190.58.150:49971] LINE 1: ..., '', '', '', '', '', '', '', '', '', '', '', '', '', '', ''..., referer: http://ec2-52-57-87-239.eu-central-1.compute.amazonaws.com/reports/new?
[Sun Sep 25 10:30:48.558384 2016] [:error] [pid 1792:tid 140667971929856] [client 88.190.58.150:49971]                                                              ^, referer: http://ec2-52-57-87-239.eu-central-1.compute.amazonaws.com/reports/new?
[Sun Sep 25 10:30:48.558388 2016] [:error] [pid 1792:tid 140667971929856] [client 88.190.58.150:49971]  'INSERT INTO report (site_name, site_full_adress, site_adress_number, site_adress_street, site_adress_postcode, site_adress_city, site_administrative_area, site_adress_country, "site_ERPcategory", "site_ERPtype", client_lastname, client_firstname, client_full_adress, client_adress_number, client_adress_street, client_adress_postcode, client_adress_city, client_administrative_area, client_adress_country, client_phone, client_mail, report_number, "report_visitDate", "report_redactionDate", report_picture, "report_pictureOrientation", editor_lastname, editor_firstname, editor_full_adress, editor_adress_number, editor_adress_street, editor_adress_postcode, editor_adress_city, editor_administrative_area, editor_adress_country, editor_phone, editor_mail, frame_choice, user_id) VALUES (%(site_name)s, %(site_full_adress)s, %(site_adress_number)s, %(site_adress_street)s, %(site_adress_postcode)s, %(site_adress_city)s, %(site_administrative_area)s, %(site_adress_country)s, %(site_ERPcategory)s, %(site_ERPtype)s, %(client_lastname)s, %(client_firstname)s, %(client_full_adress)s, %(client_adress_number)s, %(client_adress_street)s, %(client_adress_postcode)s, %(client_adress_city)s, %(client_administrative_area)s, %(client_adress_country)s, %(client_phone)s, %(client_mail)s, %(report_number)s, %(report_visitDate)s, %(report_redactionDate)s, %(report_picture)s, %(report_pictureOrientation)s, %(editor_lastname)s, %(editor_firstname)s, %(editor_full_adress)s, %(editor_adress_number)s, %(editor_adress_street)s, %(editor_adress_postcode)s, %(editor_adress_city)s, %(editor_administrative_area)s, %(editor_adress_country)s, %(editor_phone)s, %(editor_mail)s, %(frame_choice)s, %(user_id)s) RETURNING report.id' {'site_name': u'', 'report_number': u'', 'editor_full_adress': u'', 'editor_adress_street': u'', 'client_lastname': u'', 'site_ERPtype': u'', 'editor_adress_city': u'', 'client_phone': u'', 'editor_administrative_area': u'', 'client_firstname': u'', 'user_id': 3, 'site_adress_postcode': u'', 'client_full_adress': u'', 'report_visitDate': u'', 'client_adress_city': u'', 'site_adress_number': u'', 'client_adress_country': u'', 'editor_adress_postcode': u'', 'client_adress_number': u'', 'client_mail': u'', 'editor_phone': u'', 'site_adress_city': u'', 'client_adress_street': u'', 'editor_adress_number': u'', 'editor_adress_country': u'', 'report_redactionDate': u'', 'site_administrative_area': u'', 'report_pictureOrientation': 'None', 'editor_mail': u'', 'report_picture': 'undefined.jpg', 'client_administrative_area': u'', 'client_adress_postcode': u'', 'site_ERPcategory': u'', 'editor_lastname': u'', 'site_adress_street': u'', 'site_adress_country': u'', 'site_full_adress': u'', 'editor_firstname': u'', 'frame_choice': 0}, referer: http://ec2-52-57-87-239.eu-central-1.compute.amazonaws.com/reports/new?
[Sun Sep 25 10:47:57.316961 2016] [:error] [pid 1792:tid 140667980322560] [client 88.190.58.150:50319] mod_wsgi (pid=1792): Exception occurred processing WSGI script '/var/www/myapp.wsgi'., referer: http://ec2-52-57-87-239.eu-central-1.compute.amazonaws.com/
[Sun Sep 25 10:47:57.316999 2016] [:error] [pid 1792:tid 140667980322560] [client 88.190.58.150:50319] Traceback (most recent call last):, referer: http://ec2-52-57-87-239.eu-central-1.compute.amazonaws.com/
[Sun Sep 25 10:47:57.317015 2016] [:error] [pid 1792:tid 140667980322560] [client 88.190.58.150:50319]   File "/usr/lib/python2.7/dist-packages/flask/app.py", line 1836, in __call__, referer: http://ec2-52-57-87-239.eu-central-1.compute.amazonaws.com/
[Sun Sep 25 10:47:57.317034 2016] [:error] [pid 1792:tid 140667980322560] [client 88.190.58.150:50319]     return self.wsgi_app(environ, start_response), referer: http://ec2-52-57-87-239.eu-central-1.compute.amazonaws.com/
[Sun Sep 25 10:47:57.317041 2016] [:error] [pid 1792:tid 140667980322560] [client 88.190.58.150:50319]   File "/usr/lib/python2.7/dist-packages/flask/app.py", line 1820, in wsgi_app, referer: http://ec2-52-57-87-239.eu-central-1.compute.amazonaws.com/
[Sun Sep 25 10:47:57.317051 2016] [:error] [pid 1792:tid 140667980322560] [client 88.190.58.150:50319]     response = self.make_response(self.handle_exception(e)), referer: http://ec2-52-57-87-239.eu-central-1.compute.amazonaws.com/
[Sun Sep 25 10:47:57.317067 2016] [:error] [pid 1792:tid 140667980322560] [client 88.190.58.150:50319]   File "/usr/lib/python2.7/dist-packages/flask/app.py", line 1403, in handle_exception, referer: http://ec2-52-57-87-239.eu-central-1.compute.amazonaws.com/
[Sun Sep 25 10:47:57.317076 2016] [:error] [pid 1792:tid 140667980322560] [client 88.190.58.150:50319]     reraise(exc_type, exc_value, tb), referer: http://ec2-52-57-87-239.eu-central-1.compute.amazonaws.com/
[Sun Sep 25 10:47:57.317081 2016] [:error] [pid 1792:tid 140667980322560] [client 88.190.58.150:50319]   File "/usr/lib/python2.7/dist-packages/flask/app.py", line 1817, in wsgi_app, referer: http://ec2-52-57-87-239.eu-central-1.compute.amazonaws.com/
[Sun Sep 25 10:47:57.317088 2016] [:error] [pid 1792:tid 140667980322560] [client 88.190.58.150:50319]     response = self.full_dispatch_request(), referer: http://ec2-52-57-87-239.eu-central-1.compute.amazonaws.com/
[Sun Sep 25 10:47:57.317093 2016] [:error] [pid 1792:tid 140667980322560] [client 88.190.58.150:50319]   File "/usr/lib/python2.7/dist-packages/flask/app.py", line 1477, in full_dispatch_request, referer: http://ec2-52-57-87-239.eu-central-1.compute.amazonaws.com/
[Sun Sep 25 10:47:57.317100 2016] [:error] [pid 1792:tid 140667980322560] [client 88.190.58.150:50319]     rv = self.handle_user_exception(e), referer: http://ec2-52-57-87-239.eu-central-1.compute.amazonaws.com/
[Sun Sep 25 10:47:57.317105 2016] [:error] [pid 1792:tid 140667980322560] [client 88.190.58.150:50319]   File "/usr/lib/python2.7/dist-packages/flask/app.py", line 1381, in handle_user_exception, referer: http://ec2-52-57-87-239.eu-central-1.compute.amazonaws.com/
[Sun Sep 25 10:47:57.317112 2016] [:error] [pid 1792:tid 140667980322560] [client 88.190.58.150:50319]     reraise(exc_type, exc_value, tb), referer: http://ec2-52-57-87-239.eu-central-1.compute.amazonaws.com/
[Sun Sep 25 10:47:57.317116 2016] [:error] [pid 1792:tid 140667980322560] [client 88.190.58.150:50319]   File "/usr/lib/python2.7/dist-packages/flask/app.py", line 1475, in full_dispatch_request, referer: http://ec2-52-57-87-239.eu-central-1.compute.amazonaws.com/
[Sun Sep 25 10:47:57.317123 2016] [:error] [pid 1792:tid 140667980322560] [client 88.190.58.150:50319]     rv = self.dispatch_request(), referer: http://ec2-52-57-87-239.eu-central-1.compute.amazonaws.com/
[Sun Sep 25 10:47:57.317128 2016] [:error] [pid 1792:tid 140667980322560] [client 88.190.58.150:50319]   File "/usr/lib/python2.7/dist-packages/flask/app.py", line 1461, in dispatch_request, referer: http://ec2-52-57-87-239.eu-central-1.compute.amazonaws.com/
[Sun Sep 25 10:47:57.317135 2016] [:error] [pid 1792:tid 140667980322560] [client 88.190.58.150:50319]     return self.view_functions[rule.endpoint](**req.view_args), referer: http://ec2-52-57-87-239.eu-central-1.compute.amazonaws.com/
[Sun Sep 25 10:47:57.317140 2016] [:error] [pid 1792:tid 140667980322560] [client 88.190.58.150:50319]   File "/var/www/ItemCatalog/finalProject.py", line 69, in decorated_function, referer: http://ec2-52-57-87-239.eu-central-1.compute.amazonaws.com/
[Sun Sep 25 10:47:57.317148 2016] [:error] [pid 1792:tid 140667980322560] [client 88.190.58.150:50319]     return f(*args, **kwargs), referer: http://ec2-52-57-87-239.eu-central-1.compute.amazonaws.com/
[Sun Sep 25 10:47:57.317152 2016] [:error] [pid 1792:tid 140667980322560] [client 88.190.58.150:50319]   File "/var/www/ItemCatalog/finalProject.py", line 524, in newSingleReport, referer: http://ec2-52-57-87-239.eu-central-1.compute.amazonaws.com/
[Sun Sep 25 10:47:57.317160 2016] [:error] [pid 1792:tid 140667980322560] [client 88.190.58.150:50319]     user=login_session), referer: http://ec2-52-57-87-239.eu-central-1.compute.amazonaws.com/
[Sun Sep 25 10:47:57.317164 2016] [:error] [pid 1792:tid 140667980322560] [client 88.190.58.150:50319]   File "/usr/lib/python2.7/dist-packages/flask/templating.py", line 128, in render_template, referer: http://ec2-52-57-87-239.eu-central-1.compute.amazonaws.com/
[Sun Sep 25 10:47:57.317246 2016] [:error] [pid 1792:tid 140667980322560] [client 88.190.58.150:50319]     context, ctx.app), referer: http://ec2-52-57-87-239.eu-central-1.compute.amazonaws.com/
[Sun Sep 25 10:47:57.317256 2016] [:error] [pid 1792:tid 140667980322560] [client 88.190.58.150:50319]   File "/usr/lib/python2.7/dist-packages/flask/templating.py", line 110, in _render, referer: http://ec2-52-57-87-239.eu-central-1.compute.amazonaws.com/
[Sun Sep 25 10:47:57.317265 2016] [:error] [pid 1792:tid 140667980322560] [client 88.190.58.150:50319]     rv = template.render(context), referer: http://ec2-52-57-87-239.eu-central-1.compute.amazonaws.com/
[Sun Sep 25 10:47:57.317270 2016] [:error] [pid 1792:tid 140667980322560] [client 88.190.58.150:50319]   File "/usr/lib/python2.7/dist-packages/jinja2/environment.py", line 969, in render, referer: http://ec2-52-57-87-239.eu-central-1.compute.amazonaws.com/
[Sun Sep 25 10:47:57.317522 2016] [:error] [pid 1792:tid 140667980322560] [client 88.190.58.150:50319]     return self.environment.handle_exception(exc_info, True), referer: http://ec2-52-57-87-239.eu-central-1.compute.amazonaws.com/
[Sun Sep 25 10:47:57.317534 2016] [:error] [pid 1792:tid 140667980322560] [client 88.190.58.150:50319]   File "/usr/lib/python2.7/dist-packages/jinja2/environment.py", line 742, in handle_exception, referer: http://ec2-52-57-87-239.eu-central-1.compute.amazonaws.com/
[Sun Sep 25 10:47:57.317545 2016] [:error] [pid 1792:tid 140667980322560] [client 88.190.58.150:50319]     reraise(exc_type, exc_value, tb), referer: http://ec2-52-57-87-239.eu-central-1.compute.amazonaws.com/
[Sun Sep 25 10:47:57.317551 2016] [:error] [pid 1792:tid 140667980322560] [client 88.190.58.150:50319]   File "/var/www/ItemCatalog/templates/createsinglereport.html", line 86, in top-level template code, referer: http://ec2-52-57-87-239.eu-central-1.compute.amazonaws.com/
[Sun Sep 25 10:47:57.317664 2016] [:error] [pid 1792:tid 140667980322560] [client 88.190.58.150:50319]     {% for i in frames %}, referer: http://ec2-52-57-87-239.eu-central-1.compute.amazonaws.com/
[Sun Sep 25 10:47:57.317674 2016] [:error] [pid 1792:tid 140667980322560] [client 88.190.58.150:50319]   File "/usr/lib/python2.7/dist-packages/sqlalchemy/orm/query.py", line 2353, in __iter__, referer: http://ec2-52-57-87-239.eu-central-1.compute.amazonaws.com/
[Sun Sep 25 10:47:57.318257 2016] [:error] [pid 1792:tid 140667980322560] [client 88.190.58.150:50319]     return self._execute_and_instances(context), referer: http://ec2-52-57-87-239.eu-central-1.compute.amazonaws.com/
[Sun Sep 25 10:47:57.318268 2016] [:error] [pid 1792:tid 140667980322560] [client 88.190.58.150:50319]   File "/usr/lib/python2.7/dist-packages/sqlalchemy/orm/query.py", line 2366, in _execute_and_instances, referer: http://ec2-52-57-87-239.eu-central-1.compute.amazonaws.com/
[Sun Sep 25 10:47:57.318281 2016] [:error] [pid 1792:tid 140667980322560] [client 88.190.58.150:50319]     close_with_result=True), referer: http://ec2-52-57-87-239.eu-central-1.compute.amazonaws.com/
[Sun Sep 25 10:47:57.318286 2016] [:error] [pid 1792:tid 140667980322560] [client 88.190.58.150:50319]   File "/usr/lib/python2.7/dist-packages/sqlalchemy/orm/query.py", line 2357, in _connection_from_session, referer: http://ec2-52-57-87-239.eu-central-1.compute.amazonaws.com/
[Sun Sep 25 10:47:57.318294 2016] [:error] [pid 1792:tid 140667980322560] [client 88.190.58.150:50319]     **kw), referer: http://ec2-52-57-87-239.eu-central-1.compute.amazonaws.com/
[Sun Sep 25 10:47:57.318298 2016] [:error] [pid 1792:tid 140667980322560] [client 88.190.58.150:50319]   File "/usr/lib/python2.7/dist-packages/sqlalchemy/orm/session.py", line 799, in connection, referer: http://ec2-52-57-87-239.eu-central-1.compute.amazonaws.com/
[Sun Sep 25 10:47:57.318307 2016] [:error] [pid 1792:tid 140667980322560] [client 88.190.58.150:50319]     close_with_result=close_with_result), referer: http://ec2-52-57-87-239.eu-central-1.compute.amazonaws.com/
[Sun Sep 25 10:47:57.318316 2016] [:error] [pid 1792:tid 140667980322560] [client 88.190.58.150:50319]   File "/usr/lib/python2.7/dist-packages/sqlalchemy/orm/session.py", line 803, in _connection_for_bind, referer: http://ec2-52-57-87-239.eu-central-1.compute.amazonaws.com/
[Sun Sep 25 10:47:57.318325 2016] [:error] [pid 1792:tid 140667980322560] [client 88.190.58.150:50319]     return self.transaction._connection_for_bind(engine), referer: http://ec2-52-57-87-239.eu-central-1.compute.amazonaws.com/
[Sun Sep 25 10:47:57.318330 2016] [:error] [pid 1792:tid 140667980322560] [client 88.190.58.150:50319]   File "/usr/lib/python2.7/dist-packages/sqlalchemy/orm/session.py", line 282, in _connection_for_bind, referer: http://ec2-52-57-87-239.eu-central-1.compute.amazonaws.com/
[Sun Sep 25 10:47:57.318337 2016] [:error] [pid 1792:tid 140667980322560] [client 88.190.58.150:50319]     self._assert_active(), referer: http://ec2-52-57-87-239.eu-central-1.compute.amazonaws.com/
[Sun Sep 25 10:47:57.318342 2016] [:error] [pid 1792:tid 140667980322560] [client 88.190.58.150:50319]   File "/usr/lib/python2.7/dist-packages/sqlalchemy/orm/session.py", line 194, in _assert_active, referer: http://ec2-52-57-87-239.eu-central-1.compute.amazonaws.com/
[Sun Sep 25 10:47:57.318349 2016] [:error] [pid 1792:tid 140667980322560] [client 88.190.58.150:50319]     % self._rollback_exception, referer: http://ec2-52-57-87-239.eu-central-1.compute.amazonaws.com/
[Sun Sep 25 10:47:57.318364 2016] [:error] [pid 1792:tid 140667980322560] [client 88.190.58.150:50319] InvalidRequestError: This Session's transaction has been rolled back due to a previous exception during flush. To begin a new transaction with this Session, first issue Session.rollback(). Original exception was: (DataError) invalid input syntax for integer: "", referer: http://ec2-52-57-87-239.eu-central-1.compute.amazonaws.com/
[Sun Sep 25 10:47:57.318367 2016] [:error] [pid 1792:tid 140667980322560] [client 88.190.58.150:50319] LINE 1: ..., '', '', '', '', '', '', '', '', '', '', '', '', '', '', ''..., referer: http://ec2-52-57-87-239.eu-central-1.compute.amazonaws.com/
[Sun Sep 25 10:47:57.318370 2016] [:error] [pid 1792:tid 140667980322560] [client 88.190.58.150:50319]                                                              ^, referer: http://ec2-52-57-87-239.eu-central-1.compute.amazonaws.com/
[Sun Sep 25 10:47:57.318374 2016] [:error] [pid 1792:tid 140667980322560] [client 88.190.58.150:50319]  'INSERT INTO report (site_name, site_full_adress, site_adress_number, site_adress_street, site_adress_postcode, site_adress_city, site_administrative_area, site_adress_country, "site_ERPcategory", "site_ERPtype", client_lastname, client_firstname, client_full_adress, client_adress_number, client_adress_street, client_adress_postcode, client_adress_city, client_administrative_area, client_adress_country, client_phone, client_mail, report_number, "report_visitDate", "report_redactionDate", report_picture, "report_pictureOrientation", editor_lastname, editor_firstname, editor_full_adress, editor_adress_number, editor_adress_street, editor_adress_postcode, editor_adress_city, editor_administrative_area, editor_adress_country, editor_phone, editor_mail, frame_choice, user_id) VALUES (%(site_name)s, %(site_full_adress)s, %(site_adress_number)s, %(site_adress_street)s, %(site_adress_postcode)s, %(site_adress_city)s, %(site_administrative_area)s, %(site_adress_country)s, %(site_ERPcategory)s, %(site_ERPtype)s, %(client_lastname)s, %(client_firstname)s, %(client_full_adress)s, %(client_adress_number)s, %(client_adress_street)s, %(client_adress_postcode)s, %(client_adress_city)s, %(client_administrative_area)s, %(client_adress_country)s, %(client_phone)s, %(client_mail)s, %(report_number)s, %(report_visitDate)s, %(report_redactionDate)s, %(report_picture)s, %(report_pictureOrientation)s, %(editor_lastname)s, %(editor_firstname)s, %(editor_full_adress)s, %(editor_adress_number)s, %(editor_adress_street)s, %(editor_adress_postcode)s, %(editor_adress_city)s, %(editor_administrative_area)s, %(editor_adress_country)s, %(editor_phone)s, %(editor_mail)s, %(frame_choice)s, %(user_id)s) RETURNING report.id' {'site_name': u'', 'report_number': u'', 'editor_full_adress': u'', 'editor_adress_street': u'', 'client_lastname': u'', 'site_ERPtype': u'', 'editor_adress_city': u'', 'client_phone': u'', 'editor_administrative_area': u'', 'client_firstname': u'', 'user_id': 3, 'site_adress_postcode': u'', 'client_full_adress': u'', 'report_visitDate': u'', 'client_adress_city': u'', 'site_adress_number': u'', 'client_adress_country': u'', 'editor_adress_postcode': u'', 'client_adress_number': u'', 'client_mail': u'', 'editor_phone': u'', 'site_adress_city': u'', 'client_adress_street': u'', 'editor_adress_number': u'', 'editor_adress_country': u'', 'report_redactionDate': u'', 'site_administrative_area': u'', 'report_pictureOrientation': 'None', 'editor_mail': u'', 'report_picture': 'undefined.jpg', 'client_administrative_area': u'', 'client_adress_postcode': u'', 'site_ERPcategory': u'', 'editor_lastname': u'', 'site_adress_street': u'', 'site_adress_country': u'', 'site_full_adress': u'', 'editor_firstname': u'', 'frame_choice': 0}, referer: http://ec2-52-57-87-239.eu-central-1.compute.amazonaws.com/
[Sun Sep 25 10:50:20.841986 2016] [mpm_event:notice] [pid 1789:tid 140668225419136] AH00491: caught SIGTERM, shutting down
[Sun Sep 25 10:50:21.830141 2016] [mpm_event:notice] [pid 2034:tid 140024951416704] AH00489: Apache/2.4.7 (Ubuntu) mod_wsgi/3.4 Python/2.7.6 configured -- resuming normal operations
[Sun Sep 25 10:50:21.830211 2016] [core:notice] [pid 2034:tid 140024951416704] AH00094: Command line: '/usr/sbin/apache2'
[Sun Sep 25 10:50:28.121372 2016] [:info] [pid 2037:tid 140024807732992] [client 88.190.58.150:50360] mod_wsgi (pid=2037, process='', application='ec2-52-57-15-38.eu-central-1.compute.amazonaws.com|'): Loading WSGI script '/var/www/myapp.wsgi'.
[Sun Sep 25 10:50:28.148177 2016] [:info] [pid 2038:tid 140024632788736] [client 88.190.58.150:50362] mod_wsgi (pid=2038, process='', application='ec2-52-57-15-38.eu-central-1.compute.amazonaws.com|'): Loading WSGI script '/var/www/myapp.wsgi'.
[Sun Sep 25 10:50:36.398862 2016] [:error] [pid 2038:tid 140024725108480] [client 88.190.58.150:50361] mod_wsgi (pid=2038): Exception occurred processing WSGI script '/var/www/myapp.wsgi'., referer: http://ec2-52-57-87-239.eu-central-1.compute.amazonaws.com/reports/new?
[Sun Sep 25 10:50:36.398892 2016] [:error] [pid 2038:tid 140024725108480] [client 88.190.58.150:50361] Traceback (most recent call last):, referer: http://ec2-52-57-87-239.eu-central-1.compute.amazonaws.com/reports/new?
[Sun Sep 25 10:50:36.398906 2016] [:error] [pid 2038:tid 140024725108480] [client 88.190.58.150:50361]   File "/usr/lib/python2.7/dist-packages/flask/app.py", line 1836, in __call__, referer: http://ec2-52-57-87-239.eu-central-1.compute.amazonaws.com/reports/new?
[Sun Sep 25 10:50:36.399343 2016] [:error] [pid 2038:tid 140024725108480] [client 88.190.58.150:50361]     return self.wsgi_app(environ, start_response), referer: http://ec2-52-57-87-239.eu-central-1.compute.amazonaws.com/reports/new?
[Sun Sep 25 10:50:36.399359 2016] [:error] [pid 2038:tid 140024725108480] [client 88.190.58.150:50361]   File "/usr/lib/python2.7/dist-packages/flask/app.py", line 1820, in wsgi_app, referer: http://ec2-52-57-87-239.eu-central-1.compute.amazonaws.com/reports/new?
[Sun Sep 25 10:50:36.399373 2016] [:error] [pid 2038:tid 140024725108480] [client 88.190.58.150:50361]     response = self.make_response(self.handle_exception(e)), referer: http://ec2-52-57-87-239.eu-central-1.compute.amazonaws.com/reports/new?
[Sun Sep 25 10:50:36.399380 2016] [:error] [pid 2038:tid 140024725108480] [client 88.190.58.150:50361]   File "/usr/lib/python2.7/dist-packages/flask/app.py", line 1403, in handle_exception, referer: http://ec2-52-57-87-239.eu-central-1.compute.amazonaws.com/reports/new?
[Sun Sep 25 10:50:36.399388 2016] [:error] [pid 2038:tid 140024725108480] [client 88.190.58.150:50361]     reraise(exc_type, exc_value, tb), referer: http://ec2-52-57-87-239.eu-central-1.compute.amazonaws.com/reports/new?
[Sun Sep 25 10:50:36.399400 2016] [:error] [pid 2038:tid 140024725108480] [client 88.190.58.150:50361]   File "/usr/lib/python2.7/dist-packages/flask/app.py", line 1817, in wsgi_app, referer: http://ec2-52-57-87-239.eu-central-1.compute.amazonaws.com/reports/new?
[Sun Sep 25 10:50:36.399409 2016] [:error] [pid 2038:tid 140024725108480] [client 88.190.58.150:50361]     response = self.full_dispatch_request(), referer: http://ec2-52-57-87-239.eu-central-1.compute.amazonaws.com/reports/new?
[Sun Sep 25 10:50:36.399414 2016] [:error] [pid 2038:tid 140024725108480] [client 88.190.58.150:50361]   File "/usr/lib/python2.7/dist-packages/flask/app.py", line 1477, in full_dispatch_request, referer: http://ec2-52-57-87-239.eu-central-1.compute.amazonaws.com/reports/new?
[Sun Sep 25 10:50:36.399421 2016] [:error] [pid 2038:tid 140024725108480] [client 88.190.58.150:50361]     rv = self.handle_user_exception(e), referer: http://ec2-52-57-87-239.eu-central-1.compute.amazonaws.com/reports/new?
[Sun Sep 25 10:50:36.399426 2016] [:error] [pid 2038:tid 140024725108480] [client 88.190.58.150:50361]   File "/usr/lib/python2.7/dist-packages/flask/app.py", line 1381, in handle_user_exception, referer: http://ec2-52-57-87-239.eu-central-1.compute.amazonaws.com/reports/new?
[Sun Sep 25 10:50:36.399433 2016] [:error] [pid 2038:tid 140024725108480] [client 88.190.58.150:50361]     reraise(exc_type, exc_value, tb), referer: http://ec2-52-57-87-239.eu-central-1.compute.amazonaws.com/reports/new?
[Sun Sep 25 10:50:36.399437 2016] [:error] [pid 2038:tid 140024725108480] [client 88.190.58.150:50361]   File "/usr/lib/python2.7/dist-packages/flask/app.py", line 1475, in full_dispatch_request, referer: http://ec2-52-57-87-239.eu-central-1.compute.amazonaws.com/reports/new?
[Sun Sep 25 10:50:36.399444 2016] [:error] [pid 2038:tid 140024725108480] [client 88.190.58.150:50361]     rv = self.dispatch_request(), referer: http://ec2-52-57-87-239.eu-central-1.compute.amazonaws.com/reports/new?
[Sun Sep 25 10:50:36.399449 2016] [:error] [pid 2038:tid 140024725108480] [client 88.190.58.150:50361]   File "/usr/lib/python2.7/dist-packages/flask/app.py", line 1461, in dispatch_request, referer: http://ec2-52-57-87-239.eu-central-1.compute.amazonaws.com/reports/new?
[Sun Sep 25 10:50:36.399469 2016] [:error] [pid 2038:tid 140024725108480] [client 88.190.58.150:50361]     return self.view_functions[rule.endpoint](**req.view_args), referer: http://ec2-52-57-87-239.eu-central-1.compute.amazonaws.com/reports/new?
[Sun Sep 25 10:50:36.399474 2016] [:error] [pid 2038:tid 140024725108480] [client 88.190.58.150:50361]   File "/var/www/ItemCatalog/finalProject.py", line 69, in decorated_function, referer: http://ec2-52-57-87-239.eu-central-1.compute.amazonaws.com/reports/new?
[Sun Sep 25 10:50:36.399626 2016] [:error] [pid 2038:tid 140024725108480] [client 88.190.58.150:50361]     return f(*args, **kwargs), referer: http://ec2-52-57-87-239.eu-central-1.compute.amazonaws.com/reports/new?
[Sun Sep 25 10:50:36.399637 2016] [:error] [pid 2038:tid 140024725108480] [client 88.190.58.150:50361]   File "/var/www/ItemCatalog/finalProject.py", line 503, in newSingleReport, referer: http://ec2-52-57-87-239.eu-central-1.compute.amazonaws.com/reports/new?
[Sun Sep 25 10:50:36.399647 2016] [:error] [pid 2038:tid 140024725108480] [client 88.190.58.150:50361]     session.commit(), referer: http://ec2-52-57-87-239.eu-central-1.compute.amazonaws.com/reports/new?
[Sun Sep 25 10:50:36.399652 2016] [:error] [pid 2038:tid 140024725108480] [client 88.190.58.150:50361]   File "/usr/lib/python2.7/dist-packages/sqlalchemy/orm/session.py", line 721, in commit, referer: http://ec2-52-57-87-239.eu-central-1.compute.amazonaws.com/reports/new?
[Sun Sep 25 10:50:36.400020 2016] [:error] [pid 2038:tid 140024725108480] [client 88.190.58.150:50361]     self.transaction.commit(), referer: http://ec2-52-57-87-239.eu-central-1.compute.amazonaws.com/reports/new?
[Sun Sep 25 10:50:36.400030 2016] [:error] [pid 2038:tid 140024725108480] [client 88.190.58.150:50361]   File "/usr/lib/python2.7/dist-packages/sqlalchemy/orm/session.py", line 354, in commit, referer: http://ec2-52-57-87-239.eu-central-1.compute.amazonaws.com/reports/new?
[Sun Sep 25 10:50:36.400060 2016] [:error] [pid 2038:tid 140024725108480] [client 88.190.58.150:50361]     self._prepare_impl(), referer: http://ec2-52-57-87-239.eu-central-1.compute.amazonaws.com/reports/new?
[Sun Sep 25 10:50:36.400066 2016] [:error] [pid 2038:tid 140024725108480] [client 88.190.58.150:50361]   File "/usr/lib/python2.7/dist-packages/sqlalchemy/orm/session.py", line 334, in _prepare_impl, referer: http://ec2-52-57-87-239.eu-central-1.compute.amazonaws.com/reports/new?
[Sun Sep 25 10:50:36.400074 2016] [:error] [pid 2038:tid 140024725108480] [client 88.190.58.150:50361]     self.session.flush(), referer: http://ec2-52-57-87-239.eu-central-1.compute.amazonaws.com/reports/new?
[Sun Sep 25 10:50:36.400079 2016] [:error] [pid 2038:tid 140024725108480] [client 88.190.58.150:50361]   File "/usr/lib/python2.7/dist-packages/sqlalchemy/orm/session.py", line 1818, in flush, referer: http://ec2-52-57-87-239.eu-central-1.compute.amazonaws.com/reports/new?
[Sun Sep 25 10:50:36.400085 2016] [:error] [pid 2038:tid 140024725108480] [client 88.190.58.150:50361]     self._flush(objects), referer: http://ec2-52-57-87-239.eu-central-1.compute.amazonaws.com/reports/new?
[Sun Sep 25 10:50:36.400090 2016] [:error] [pid 2038:tid 140024725108480] [client 88.190.58.150:50361]   File "/usr/lib/python2.7/dist-packages/sqlalchemy/orm/session.py", line 1936, in _flush, referer: http://ec2-52-57-87-239.eu-central-1.compute.amazonaws.com/reports/new?
[Sun Sep 25 10:50:36.400097 2016] [:error] [pid 2038:tid 140024725108480] [client 88.190.58.150:50361]     transaction.rollback(_capture_exception=True), referer: http://ec2-52-57-87-239.eu-central-1.compute.amazonaws.com/reports/new?
[Sun Sep 25 10:50:36.400102 2016] [:error] [pid 2038:tid 140024725108480] [client 88.190.58.150:50361]   File "/usr/lib/python2.7/dist-packages/sqlalchemy/util/langhelpers.py", line 58, in __exit__, referer: http://ec2-52-57-87-239.eu-central-1.compute.amazonaws.com/reports/new?
[Sun Sep 25 10:50:36.400285 2016] [:error] [pid 2038:tid 140024725108480] [client 88.190.58.150:50361]     compat.reraise(exc_type, exc_value, exc_tb), referer: http://ec2-52-57-87-239.eu-central-1.compute.amazonaws.com/reports/new?
[Sun Sep 25 10:50:36.400294 2016] [:error] [pid 2038:tid 140024725108480] [client 88.190.58.150:50361]   File "/usr/lib/python2.7/dist-packages/sqlalchemy/orm/session.py", line 1900, in _flush, referer: http://ec2-52-57-87-239.eu-central-1.compute.amazonaws.com/reports/new?
[Sun Sep 25 10:50:36.400303 2016] [:error] [pid 2038:tid 140024725108480] [client 88.190.58.150:50361]     flush_context.execute(), referer: http://ec2-52-57-87-239.eu-central-1.compute.amazonaws.com/reports/new?
[Sun Sep 25 10:50:36.400308 2016] [:error] [pid 2038:tid 140024725108480] [client 88.190.58.150:50361]   File "/usr/lib/python2.7/dist-packages/sqlalchemy/orm/unitofwork.py", line 372, in execute, referer: http://ec2-52-57-87-239.eu-central-1.compute.amazonaws.com/reports/new?
[Sun Sep 25 10:50:36.400428 2016] [:error] [pid 2038:tid 140024725108480] [client 88.190.58.150:50361]     rec.execute(self), referer: http://ec2-52-57-87-239.eu-central-1.compute.amazonaws.com/reports/new?
[Sun Sep 25 10:50:36.400436 2016] [:error] [pid 2038:tid 140024725108480] [client 88.190.58.150:50361]   File "/usr/lib/python2.7/dist-packages/sqlalchemy/orm/unitofwork.py", line 525, in execute, referer: http://ec2-52-57-87-239.eu-central-1.compute.amazonaws.com/reports/new?
[Sun Sep 25 10:50:36.400446 2016] [:error] [pid 2038:tid 140024725108480] [client 88.190.58.150:50361]     uow, referer: http://ec2-52-57-87-239.eu-central-1.compute.amazonaws.com/reports/new?
[Sun Sep 25 10:50:36.400451 2016] [:error] [pid 2038:tid 140024725108480] [client 88.190.58.150:50361]   File "/usr/lib/python2.7/dist-packages/sqlalchemy/orm/persistence.py", line 64, in save_obj, referer: http://ec2-52-57-87-239.eu-central-1.compute.amazonaws.com/reports/new?
[Sun Sep 25 10:50:36.400638 2016] [:error] [pid 2038:tid 140024725108480] [client 88.190.58.150:50361]     table, insert), referer: http://ec2-52-57-87-239.eu-central-1.compute.amazonaws.com/reports/new?
[Sun Sep 25 10:50:36.400651 2016] [:error] [pid 2038:tid 140024725108480] [client 88.190.58.150:50361]   File "/usr/lib/python2.7/dist-packages/sqlalchemy/orm/persistence.py", line 569, in _emit_insert_statements, referer: http://ec2-52-57-87-239.eu-central-1.compute.amazonaws.com/reports/new?
[Sun Sep 25 10:50:36.400662 2016] [:error] [pid 2038:tid 140024725108480] [client 88.190.58.150:50361]     execute(statement, params), referer: http://ec2-52-57-87-239.eu-central-1.compute.amazonaws.com/reports/new?
[Sun Sep 25 10:50:36.400668 2016] [:error] [pid 2038:tid 140024725108480] [client 88.190.58.150:50361]   File "/usr/lib/python2.7/dist-packages/sqlalchemy/engine/base.py", line 662, in execute, referer: http://ec2-52-57-87-239.eu-central-1.compute.amazonaws.com/reports/new?
[Sun Sep 25 10:50:36.400969 2016] [:error] [pid 2038:tid 140024725108480] [client 88.190.58.150:50361]     params), referer: http://ec2-52-57-87-239.eu-central-1.compute.amazonaws.com/reports/new?
[Sun Sep 25 10:50:36.400978 2016] [:error] [pid 2038:tid 140024725108480] [client 88.190.58.150:50361]   File "/usr/lib/python2.7/dist-packages/sqlalchemy/engine/base.py", line 761, in _execute_clauseelement, referer: http://ec2-52-57-87-239.eu-central-1.compute.amazonaws.com/reports/new?
[Sun Sep 25 10:50:36.400988 2016] [:error] [pid 2038:tid 140024725108480] [client 88.190.58.150:50361]     compiled_sql, distilled_params, referer: http://ec2-52-57-87-239.eu-central-1.compute.amazonaws.com/reports/new?
[Sun Sep 25 10:50:36.400993 2016] [:error] [pid 2038:tid 140024725108480] [client 88.190.58.150:50361]   File "/usr/lib/python2.7/dist-packages/sqlalchemy/engine/base.py", line 874, in _execute_context, referer: http://ec2-52-57-87-239.eu-central-1.compute.amazonaws.com/reports/new?
[Sun Sep 25 10:50:36.401000 2016] [:error] [pid 2038:tid 140024725108480] [client 88.190.58.150:50361]     context), referer: http://ec2-52-57-87-239.eu-central-1.compute.amazonaws.com/reports/new?
[Sun Sep 25 10:50:36.401005 2016] [:error] [pid 2038:tid 140024725108480] [client 88.190.58.150:50361]   File "/usr/lib/python2.7/dist-packages/sqlalchemy/engine/base.py", line 1024, in _handle_dbapi_exception, referer: http://ec2-52-57-87-239.eu-central-1.compute.amazonaws.com/reports/new?
[Sun Sep 25 10:50:36.401011 2016] [:error] [pid 2038:tid 140024725108480] [client 88.190.58.150:50361]     exc_info, referer: http://ec2-52-57-87-239.eu-central-1.compute.amazonaws.com/reports/new?
[Sun Sep 25 10:50:36.401016 2016] [:error] [pid 2038:tid 140024725108480] [client 88.190.58.150:50361]   File "/usr/lib/python2.7/dist-packages/sqlalchemy/util/compat.py", line 196, in raise_from_cause, referer: http://ec2-52-57-87-239.eu-central-1.compute.amazonaws.com/reports/new?
[Sun Sep 25 10:50:36.401060 2016] [:error] [pid 2038:tid 140024725108480] [client 88.190.58.150:50361]     reraise(type(exception), exception, tb=exc_tb), referer: http://ec2-52-57-87-239.eu-central-1.compute.amazonaws.com/reports/new?
[Sun Sep 25 10:50:36.401066 2016] [:error] [pid 2038:tid 140024725108480] [client 88.190.58.150:50361]   File "/usr/lib/python2.7/dist-packages/sqlalchemy/engine/base.py", line 867, in _execute_context, referer: http://ec2-52-57-87-239.eu-central-1.compute.amazonaws.com/reports/new?
[Sun Sep 25 10:50:36.401074 2016] [:error] [pid 2038:tid 140024725108480] [client 88.190.58.150:50361]     context), referer: http://ec2-52-57-87-239.eu-central-1.compute.amazonaws.com/reports/new?
[Sun Sep 25 10:50:36.401079 2016] [:error] [pid 2038:tid 140024725108480] [client 88.190.58.150:50361]   File "/usr/lib/python2.7/dist-packages/sqlalchemy/engine/default.py", line 324, in do_execute, referer: http://ec2-52-57-87-239.eu-central-1.compute.amazonaws.com/reports/new?
[Sun Sep 25 10:50:36.401224 2016] [:error] [pid 2038:tid 140024725108480] [client 88.190.58.150:50361]     cursor.execute(statement, parameters), referer: http://ec2-52-57-87-239.eu-central-1.compute.amazonaws.com/reports/new?
[Sun Sep 25 10:50:36.401288 2016] [:error] [pid 2038:tid 140024725108480] [client 88.190.58.150:50361] IntegrityError: (IntegrityError) insert or update on table "report" violates foreign key constraint "report_frame_choice_fkey", referer: http://ec2-52-57-87-239.eu-central-1.compute.amazonaws.com/reports/new?
[Sun Sep 25 10:50:36.401292 2016] [:error] [pid 2038:tid 140024725108480] [client 88.190.58.150:50361] DETAIL:  Key (frame_choice)=(0) is not present in table "frame"., referer: http://ec2-52-57-87-239.eu-central-1.compute.amazonaws.com/reports/new?
[Sun Sep 25 10:50:36.401296 2016] [:error] [pid 2038:tid 140024725108480] [client 88.190.58.150:50361]  'INSERT INTO report (site_name, site_full_adress, site_adress_number, site_adress_street, site_adress_postcode, site_adress_city, site_administrative_area, site_adress_country, "site_ERPcategory", "site_ERPtype", client_lastname, client_firstname, client_full_adress, client_adress_number, client_adress_street, client_adress_postcode, client_adress_city, client_administrative_area, client_adress_country, client_phone, client_mail, report_number, "report_visitDate", "report_redactionDate", report_picture, "report_pictureOrientation", editor_lastname, editor_firstname, editor_full_adress, editor_adress_number, editor_adress_street, editor_adress_postcode, editor_adress_city, editor_administrative_area, editor_adress_country, editor_phone, editor_mail, frame_choice, user_id) VALUES (%(site_name)s, %(site_full_adress)s, %(site_adress_number)s, %(site_adress_street)s, %(site_adress_postcode)s, %(site_adress_city)s, %(site_administrative_area)s, %(site_adress_country)s, %(site_ERPcategory)s, %(site_ERPtype)s, %(client_lastname)s, %(client_firstname)s, %(client_full_adress)s, %(client_adress_number)s, %(client_adress_street)s, %(client_adress_postcode)s, %(client_adress_city)s, %(client_administrative_area)s, %(client_adress_country)s, %(client_phone)s, %(client_mail)s, %(report_number)s, %(report_visitDate)s, %(report_redactionDate)s, %(report_picture)s, %(report_pictureOrientation)s, %(editor_lastname)s, %(editor_firstname)s, %(editor_full_adress)s, %(editor_adress_number)s, %(editor_adress_street)s, %(editor_adress_postcode)s, %(editor_adress_city)s, %(editor_administrative_area)s, %(editor_adress_country)s, %(editor_phone)s, %(editor_mail)s, %(frame_choice)s, %(user_id)s) RETURNING report.id' {'site_name': u'', 'report_number': u'0987', 'editor_full_adress': u'', 'client_adress_number': u'', 'client_lastname': u'', 'site_ERPtype': u'', 'client_phone': u'', 'editor_adress_city': u'', 'editor_administrative_area': u'', 'client_firstname': u'', 'user_id': 3, 'report_redactionDate': u'', 'client_full_adress': u'', 'report_visitDate': u'', 'client_adress_city': u'', 'site_adress_number': u'', 'client_adress_country': u'', 'editor_adress_postcode': u'', 'editor_adress_street': u'', 'site_adress_country': u'', 'editor_phone': u'', 'site_adress_city': u'', 'client_adress_street': u'', 'editor_adress_number': u'', 'editor_adress_country': u'', 'site_adress_postcode': u'', 'site_administrative_area': u'', 'report_pictureOrientation': 'None', 'editor_mail': u'', 'report_picture': 'undefined.jpg', 'editor_lastname': u'', 'client_adress_postcode': u'', 'site_ERPcategory': u'', 'client_administrative_area': u'', 'site_adress_street': u'', 'client_mail': u'', 'site_full_adress': u'', 'editor_firstname': u'', 'frame_choice': 0}, referer: http://ec2-52-57-87-239.eu-central-1.compute.amazonaws.com/reports/new?
